Workbook
Name _1_DtG: #REF!
Name _1_DtG: #REF!
Name _1_DtG: #REF!
Name actSheetName: "Manual Contract extract"
Name divgrp: #REF!
Name divgrp: #REF!
Name divgrp: #REF!
Name divgrp1: #REF!
Name divgrp1: #REF!
Name divlst: #REF!
Name HlookupDTG: #REF!
Name majgrp: #REF!
Name majgrp: #REF!
Name majgrp: #REF!
Name majgrpp: #REF!
Name majgrpp: #REF!
Name majlst: #REF!
Name tm1\\_0_C: 'FIRM Load Pull'!$E$9:$R$12
Name tm1\\_0_H: "{ ""server"" : ""https://paprd-wdc1-apexpaw-01.limited-use.ibm.com"", ""cube"" : ""{ \""server\"" : \""loadtgts\"", \""cube\"" : \""loadtgts\""}""}"
Name tm1\\_0_H_1: "{ ""server"" : ""https://b01acidbc002.ahe.pok.ibm.com:9514"", ""cube"" : ""{ \""server\"" : \""loadtgts\"", \""cube\"" : \""streamload\""}"", ""CubeCaption"" : ""streamload""}"
Name tm1\\_0_H_2: "{ ""server"" : ""https://prdpaw01.sl.bluecloud.ibm.com"", ""cube"" : ""{ \""server\"" : \""loadtgts\"", \""cube\"" : \""streamload\""}"", ""CubeCaption"" : ""streamload""}"
Name tm1\\_0_R: 'FIRM Load Pull'!$C$13:$D$146
Name tm1\\_0_S: 'FIRM Load Pull'!$C$4:$C$8
Name tm1\\_1_C: graph!$D$11:$AD$14
Name tm1\\_1_H: "{ ""server"" : ""https://paprd-wdc1-apexpaw-01.limited-use.ibm.com"", ""cube"" : ""{ \""server\"" : \""loadtgts\"", \""cube\"" : \""loadtgts\""}""}"
Name tm1\\_1_H_1: "{ ""server"" : ""https://b01acidbc002.ahe.pok.ibm.com:9514"", ""cube"" : ""{ \""server\"" : \""loadtgts\"", \""cube\"" : \""streamload\""}"", ""CubeCaption"" : ""streamload""}"
Name tm1\\_1_H_2: "{ ""server"" : ""https://prdpaw01.sl.bluecloud.ibm.com"", ""cube"" : ""{ \""server\"" : \""loadtgts\"", \""cube\"" : \""streamload\""}"", ""CubeCaption"" : ""streamload""}"
Name tm1\\_1_R: graph!$B$15:$C$15
Name tm1\\_1_S: graph!$B$6:$B$10
Name tm1\\_10_C: 'Tracks Pull'!$X$9:$BZ$12
Name tm1\\_10_H: "{ ""server"" : ""https://paprd-wdc1-apexpaw-01.limited-use.ibm.com"", ""cube"" : ""{ \""server\"" : \""loadtgts\"", \""cube\"" : \""tks_tgts\""}""}"
Name tm1\\_10_H_1: "{ ""server"" : ""https://b01acidbc002.ahe.pok.ibm.com:9514"", ""cube"" : ""{ \""server\"" : \""loadtgts\"", \""cube\"" : \""loadtgts\""}"", ""CubeCaption"" : ""loadtgts""}"
Name tm1\\_10_H_2: "{ ""server"" : ""https://prdpaw01.sl.bluecloud.ibm.com"", ""cube"" : ""{ \""server\"" : \""loadtgts\"", \""cube\"" : \""loadtgts\""}"", ""CubeCaption"" : ""loadtgts""}"
Name tm1\\_10_R: 'Tracks Pull'!$U$13:$W$135
Name tm1\\_10_S: 'Tracks Pull'!$V$4:$V$7
Name tm1\\_100_C: #REF!
Name tm1\\_100_R: #REF!
Name tm1\\_101_C: #REF!
Name tm1\\_101_R: #REF!
Name tm1\\_102_H: "{ ""server"" : ""https://prdpaw01.sl.bluecloud.ibm.com"", ""cube"" : ""{ \""server\"" : \""loadtgts\"", \""cube\"" : \""loadtgts\""}""}"
Name tm1\\_103_C: #REF!
Name tm1\\_103_H: "{ ""server"" : ""https://prdpaw03.sl.bluecloud.ibm.com"", ""cube"" : ""{ \""server\"" : \""wwconsol\"", \""cube\"" : \""wwconsol\""}""}"
Name tm1\\_103_R: #REF!
Name tm1\\_104_C: #REF!
Name tm1\\_104_R: #REF!
Name tm1\\_105_C: #REF!
Name tm1\\_105_R: #REF!
Name tm1\\_106_C: #REF!
Name tm1\\_106_R: #REF!
Name tm1\\_107_C: #REF!
Name tm1\\_107_R: #REF!
Name tm1\\_108_C: #REF!
Name tm1\\_108_H: "{ ""server"" : ""https://b01acidbc005.ahe.pok.ibm.com:9514"", ""cube"" : ""{ \""server\"" : \""wwconsol\"", \""cube\"" : \""wwconsol\""}"", ""CubeCaption"" : ""wwconsol""}"
Name tm1\\_108_R: #REF!
Name tm1\\_109_C: #REF!
Name tm1\\_109_R: #REF!
Name tm1\\_11_H_1: "{ ""server"" : ""https://b01acidbc002.ahe.pok.ibm.com:9514"", ""cube"" : ""{ \""server\"" : \""loadtgts\"", \""cube\"" : \""loadtgts\""}"", ""CubeCaption"" : ""loadtgts""}"
Name tm1\\_11_H_2: "{ ""server"" : ""https://prdpaw01.sl.bluecloud.ibm.com"", ""cube"" : ""{ \""server\"" : \""loadtgts\"", \""cube\"" : \""loadtgts\""}"", ""CubeCaption"" : ""loadtgts""}"
Name tm1\\_110_C: #REF!
Name tm1\\_110_H: "{ ""server"" : ""https://b01acidbc002.ahe.pok.ibm.com:9514"", ""cube"" : ""{ \""server\"" : \""loadtgts\"", \""cube\"" : \""loadtgts\""}"", ""CubeCaption"" : ""loadtgts""}"

Sheet Cognos_Office_Connection_Cache

Sheet Summary page
B3: =CONCATENATE(INPUT!B2,INPUT!B1," Firm Load") -> 4Q25 Firm Load | E3: =CONCATENATE(INPUT!B2,INPUT!B1," Retail Load") -> 4Q25 Retail Load | L3: =CONCATENATE(INPUT!B2,INPUT!B1,"QTD Firm Load") -> 4Q25QTD Firm Load | O3: =CONCATENATE(INPUT!B2,INPUT!B1,"QTD Retail Load") -> 4Q25QTD Retail Load
B5: =WW!H9 -> 448.58962 | E5: =WW!#REF! -> #REF! | H5: =E5-743-18 -> #REF! | L5: =WW!H49 -> 326.86944 | O5: =WW!#REF! -> #REF! | R5: =O5-743 -> #REF!
B6: Rev $m | E6: Rev $m | L6: Rev $m | O6: Rev $m
B7: =WW!K9 -> 0.15984053 | C7: YtY | E7: =WW!#REF! -> #REF! | F7: YtY | L7: =WW!K49 -> 0.54610409 | M7: YtY | O7: =WW!#REF! -> #REF! | P7: YtY
B8: =WW!S9 -> -217.51703 | C8: B/(W) Tracks | E8: =WW!#REF! -> #REF! | F8: B/(W) Tracks | L8: =WW!S49 -> -339.21199 | M8: B/(W) Tracks | O8: =WW!#REF! -> #REF! | P8: B/(W) Tracks
B12: =CONCATENATE(INPUT!B2,INPUT!B1," Non HW") -> 4Q25 Non HW | E12: =CONCATENATE(INPUT!B2,INPUT!B1," Total Load") -> 4Q25 Total Load | L12: =CONCATENATE(INPUT!B2,INPUT!B1,"QTD Non HW") -> 4Q25QTD Non HW | O12: =CONCATENATE(INPUT!B2,INPUT!B1,"QTD Total Load") -> 4Q25QTD Total Load
B14: =WW!Z9 -> 581.21483 | E14: =WW!AD9 -> 1029.8044 | L14: =WW!Z49 -> 432.76636 | O14: =WW!AD49 -> 759.6358
B15: Rev $m | E15: Rev $m | L15: Rev $m | O15: Rev $m
E16: =WW!AE9 -> -0.63715343 | F16: YtY | O16: =WW!AE49 -> 0.1944096 | P16: YtY
B17: =WW!AF9 -> -2256.5531 | C17: B/(W) Budget | E17: =WW!AF9 -> -2256.5531 | F17: B/(W) Budget | L17: =WW!AB49 -> 145.98805 | M17: B/(W) Budget | O17: =WW!AF49 -> 143.47589 | P17: B/(W) Budget

Sheet graph
A6: 1 | B6: [Base]
B7: TotLoad
B8: Unit of Measure
B9: Industry | G9: MTH1 | K9: MTH2 | P9: 1Q
B10: data | D10: WK1 | E10: WK2 | F10: WK3 | G10: WK4 | H10: WK5 | I10: WK6 | J10: WK7 | K10: WK8 | L10: WK9 | M10: WK10 | N10: WK11 | O10: WK12 | P10: WK13 | R10: WK1 | S10: WK2 | T10: WK3 | U10: WK4 | V10: WK5 | W10: WK6 | X10: WK7 | Y10: WK8 | Z10: WK9 | AA10: WK10 | AB10: WK11 | AC10: WK12 | AD10: WK13
D11: Channel Total | E11: Channel Total | F11: Channel Total | G11: Channel Total | H11: Channel Total | I11: Channel Total | J11: Channel Total | K11: Channel Total | L11: Channel Total | M11: Channel Total | N11: Channel Total | O11: Channel Total | P11: Channel Total | R11: Channel Total | S11: Channel Total | T11: Channel Total | U11: Channel Total | V11: Channel Total | W11: Channel Total | X11: Channel Total | Y11: Channel Total | Z11: Channel Total | AA11: Channel Total | AB11: Channel Total | AC11: Channel Total | AD11: Channel Total
D12: 4Q | E12: 4Q | F12: 4Q | G12: 4Q | H12: 4Q | I12: 4Q | J12: 4Q | K12: 4Q | L12: 4Q | M12: 4Q | N12: 4Q | O12: 4Q | P12: 4Q | R12: 4Q | S12: 4Q | T12: 4Q | U12: 4Q | V12: 4Q | W12: 4Q | X12: 4Q | Y12: 4Q | Z12: 4Q | AA12: 4Q | AB12: 4Q | AC12: 4Q | AD12: 4Q
D13: Daily Firm | E13: =D13 -> Daily Firm | F13: =D13 -> Daily Firm | G13: =D13 -> Daily Firm | H13: =G13 -> Daily Firm | I13: =H13 -> Daily Firm | J13: Daily Firm | K13: =J13 -> Daily Firm | L13: =J13 -> Daily Firm | M13: =J13 -> Daily Firm | N13: =M13 -> Daily Firm | O13: =N13 -> Daily Firm | P13: =O13 -> Daily Firm | R13: Daily Load | S13: =R13 -> Daily Load | T13: =R13 -> Daily Load | U13: =R13 -> Daily Load | V13: =U13 -> Daily Load | W13: =V13 -> Daily Load | X13: Daily Firm | Y13: =X13 -> Daily Firm | Z13: =X13 -> Daily Firm | AA13: =X13 -> Daily Firm | AB13: =AA13 -> Daily Firm | AC13: =AA13 -> Daily Firm | AD13: =AB13 -> Daily Firm
D14: Ld100424 | E14: Ld101124 | F14: Ld101824 | G14: Ld102524 | H14: Ld110124 | I14: Ld110824 | J14: Ld111524 | K14: Ld112224 | L14: Ld112924 | M14: Ld120624 | N14: Ld121324 | O14: Ld122024 | P14: Ld4Q24Final | R14: Ld100424 | S14: Ld101124 | T14: Ld101824 | U14: Ld102524 | V14: Ld110124 | W14: Ld110824 | X14: Ld111524 | Y14: Ld112224 | Z14: Ld112924 | AA14: Ld120624 | AB14: Ld121324 | AC14: Ld122024 | AD14: Ld4Q24Final
B15: EG | C15: WW-Worldwide | D15: 0 | E15: 96.998332 | F15: 155.97591 | G15: 203.79163 | H15: 305.16829 | I15: 347.00735 | J15: 397.70233 | K15: 508.92735 | L15: 743.93306 | M15: 797.41309 | N15: 997.54391 | O15: 1512.7427 | P15: 2268.954 | R15: 0 | S15: 612.21655 | T15: 661.00777 | U15: 791.23819 | V15: 1115.4992 | W15: 1441.6635 | X15: 397.70233 | Y15: 508.92735 | Z15: 743.93306 | AA15: 797.41309 | AB15: 997.54391 | AC15: 1512.7427 | AD15: 2268.954
C17: Rev $m | D17: WK1 | E17: WK2 | F17: WK3 | G17: WK4 | H17: WK5 | I17: WK6 | J17: WK7 | K17: WK8 | L17: WK9 | M17: WK10 | N17: WK11 | O17: WK12 | P17: WK13 | Q17: Rev $m | R17: WK1 | S17: WK2 | T17: WK3 | U17: WK4 | V17: WK5 | W17: WK6 | X17: WK7 | Y17: WK8 | Z17: WK9 | AA17: WK10 | AB17: WK11 | AC17: WK12 | AD17: WK13
C18: Firm Load | D18: =D15 -> 0 | E18: =E15 -> 96.998332 | F18: =F15 -> 155.97591 | G18: =G15 -> 203.79163 | H18: =H15 -> 305.16829 | I18: =I15 -> 347.00735 | J18: =J15 -> 397.70233 | K18: =K15 -> 508.92735 | ... P18: =P15 -> 2268.954 | Q18: Retail Load | R18: =R15 -> 0 | S18: =S15 -> 612.21655 | T18: =T15 -> 661.00777 | U18: =U15 -> 791.23819 | V18: =V15 -> 1115.4992 | W18: =W15 -> 1441.6635 | X18: =X15 -> 397.70233 | Y18: =Y15 -> 508.92735 | ... AD18: =AD15 -> 2268.954
C19: Firm Tracks | D19: ='Tracks Pull'!X107 -> 146.22327 | E19: ='Tracks Pull'!Y107 -> 210.57539 | F19: ='Tracks Pull'!Z107 -> 281.1178 | G19: ='Tracks Pull'!AA107 -> 346.47533 | H19: ='Tracks Pull'!AB107 -> 448.17493 | I19: ='Tracks Pull'!AC107 -> 532.44686 | J19: ='Tracks Pull'!AD107 -> 660.58244 | K19: ='Tracks Pull'!AE107 -> 870.20815 | ... P19: ='Tracks Pull'!AJ107 -> 2701.9326 | Q19: Retail Tracks | R19: ='Tracks Pull'!AZ107 -> 146.22327 | S19: ='Tracks Pull'!BA107 -> 210.57539 | T19: ='Tracks Pull'!BB107 -> 281.1178 | U19: ='Tracks Pull'!BC107 -> 346.47533 | V19: ='Tracks Pull'!BD107 -> 448.17493 | W19: ='Tracks Pull'!BE107 -> 532.44686 | X19: ='Tracks Pull'!BF107 -> 660.58244 | Y19: ='Tracks Pull'!BG107 -> 870.20815 | ... AD19: ='Tracks Pull'!BL107 -> 2701.9326
A22: 2 | C22: Firm Load by brand | F22: Retail Load by brand
C23: =WW!C10 -> Traditional z | D23: =WW!H10 -> 129.49898 | F23: =WW!C10 -> Traditional z | G23: =WW!#REF! -> #REF!
C24: =WW!C11 -> Power HW | D24: =WW!H11 -> 79.56673 | F24: =WW!C11 -> Power HW | G24: =WW!#REF! -> #REF!
C25: =WW!C12 -> Storage HW | D25: =WW!H12 -> 233.99971 | F25: =WW!C12 -> Storage HW | G25: =WW!#REF! -> #REF!
C26: GARS | D26: =WW!H14 -> 5.5241986 | F26: GARS | G26: =WW!#REF! -> #REF!
A29: 3 | C29: Firm Load by Geo | F29: Retail Load by Geo
C30: =WW!C18 -> Americas | D30: =WW!H18 -> 166.08077 | F30: =WW!C18 -> Americas | G30: =WW!#REF! -> #REF!
C31: =WW!C19 -> EMEA | D31: =WW!H19 -> 173.31338 | F31: =WW!C19 -> EMEA | G31: =WW!#REF! -> #REF!
C32: =WW!C20 -> Japan | D32: =WW!H20 -> 60.107739 | F32: =WW!C20 -> Japan | G32: =WW!#REF! -> #REF!
C33: =WW!C21 -> APAC | D33: =WW!H21 -> 43.563528 | F33: =WW!C21 -> APAC | G33: =WW!#REF! -> #REF!
C34: WW Top+GARS | D34: =WW!H22 -> 5.5241986 | F34: WW Top+GARS | G34: =WW!#REF! -> #REF!

Sheet Ref
C1: HWLoad Daily Reporting
C3: Reference Table Market Report | I3: IBM Confidential
A5: LOADCASES YTY/QTQ | L5: LOADCASES DTG/PROJECTION
F6: LOADCASES | L6: 1 | M6: =+L6+1 -> 2 | N6: =+M6+1 -> 3 | O6: =+N6+1 -> 4 | P6: =+O6+1 -> 5 | Q6: =+P6+1 -> 6 | R6: =+Q6+1 -> 7 | S6: =+R6+1 -> 8 | T6: =+S6+1 -> 9
A7: CURR_DATE | B7: CURR_QTR | C7: CURR_MTH | D7: CURR_WK | E7: CURR_DAY | F7: CURR | G7: PY | H7: PPY | I7: PQ | J7: MF_PP1 | K7: MF_PP2 | L7: CurMth&DTG | M7: CURR_DATE | N7: DTG | O7: PY | P7: PPY | Q7: CD | R7: PD | S7: PW | T7: PY
A8: 2025-10-07 | B8: 4 | C8: 10 | D8: 2 | E8: 1 | F8: LD100625 | G8: LD070824 | H8: LD101022 | I8: LD070824 | J8: LD100923 | K8: LD101022 | L8: =C8&N8 -> 1018 | M8: =A8 -> 2025-10-07 | N8: 18 | O8: LD100424 | P8: LD100423 | Q8: =F8 -> LD100625 | W8: 2025-10-07 | X8: =W8-A8 -> 0 | Y8: LD100424 | Z8: LD100423
A9: 2025-10-08 | B9: 4 | C9: 10 | D9: 2 | E9: 2 | F9: LD100725 | G9: LD070924 | H9: LD101122 | I9: LD070924 | J9: LD101023 | K9: LD101122 | L9: =C9&N9 -> 1017 | M9: =A9 -> 2025-10-08 | N9: 17 | O9: LD100724 | P9: LD100523 | Q9: =F9 -> LD100725 | R9: =Q8 -> LD100625 | W9: 2025-10-08 | X9: =W9-A9 -> 0 | Y9: LD100724 | Z9: LD100523
A10: 2025-10-09 | B10: 4 | C10: 10 | D10: 2 | E10: 3 | F10: LD100825 | G10: LD071024 | H10: LD101222 | I10: LD071024 | J10: LD101123 | K10: LD101222 | L10: =C10&N10 -> 1016 | M10: =A10 -> 2025-10-09 | N10: 16 | O10: LD100824 | P10: LD100623 | Q10: =F10 -> LD100825 | R10: =Q9 -> LD100725 | W10: 2025-10-09 | X10: =W10-A10 -> 0 | Y10: LD100824 | Z10: LD100623
A11: 2025-10-10 | B11: 4 | C11: 10 | D11: 2 | E11: 4 | F11: LD100925 | G11: LD071124 | H11: LD101322 | I11: LD071124 | J11: LD101223 | K11: LD101322 | L11: =C11&N11 -> 1015 | M11: =A11 -> 2025-10-10 | N11: 15 | O11: LD100924 | P11: LD100923 | Q11: =F11 -> LD100925 | R11: =Q10 -> LD100825 | W11: 2025-10-10 | X11: =W11-A11 -> 0 | Y11: LD100924 | Z11: LD100923
A12: 2025-10-13 | B12: 4 | C12: 10 | D12: 2 | E12: 5 | F12: LD101025 | G12: LD071224 | H12: LD011023 | I12: LD071224 | J12: LD101323 | K12: LD101422 | L12: =C12&N12 -> 1014 | M12: =A12 -> 2025-10-13 | N12: 14 | O12: LD101024 | P12: LD101023 | Q12: =F12 -> LD101025 | R12: =Q11 -> LD100925 | S12: LD070425 | T12: =+O12 -> LD101024 | W12: 2025-10-13 | X12: =W12-A12 -> 0 | Y12: LD101024 | Z12: LD101023
A13: 2025-10-14 | B13: 4 | C13: 10 | D13: 3 | E13: 1 | F13: LD101325 | G13: LD071524 | H13: LD101722 | I13: LD071524 | J13: LD101623 | K13: LD101722 | L13: =C13&N13 -> 1013 | M13: =A13 -> 2025-10-14 | N13: 13 | O13: LD101124 | P13: LD101123 | Q13: =F13 -> LD101325 | R13: =Q12 -> LD101025 | S13: =Q12 -> LD101025 | T13: =+O13 -> LD101124 | W13: 2025-10-14 | X13: =W13-A13 -> 0 | Y13: LD101124 | Z13: LD101123
A14: 2025-10-15 | B14: 4 | C14: 10 | D14: 3 | E14: 2 | F14: LD101425 | G14: LD071624 | H14: LD101822 | I14: LD071624 | J14: LD101723 | K14: LD101822 | L14: =C14&N14 -> 1012 | M14: =A14 -> 2025-10-15 | N14: 12 | O14: LD101424 | P14: LD101223 | Q14: =F14 -> LD101425 | R14: =Q13 -> LD101325 | S14: =S13 -> LD101025 | T14: =+O14 -> LD101424 | W14: 2025-10-15 | X14: =W14-A14 -> 0 | Y14: LD101424 | Z14: LD101223
A15: 2025-10-16 | B15: 4 | C15: 10 | D15: 3 | E15: 3 | F15: LD101525 | G15: LD071724 | H15: LD101922 | I15: LD071724 | J15: LD101823 | K15: LD101922 | L15: =C15&N15 -> 1011 | M15: =A15 -> 2025-10-16 | N15: 11 | O15: LD101524 | P15: LD101323 | Q15: =F15 -> LD101525 | R15: =Q14 -> LD101425 | S15: =S14 -> LD101025 | T15: =+O15 -> LD101524 | W15: 2025-10-16 | X15: =W15-A15 -> 0 | Y15: LD101524 | Z15: LD101323
A16: 2025-10-17 | B16: 4 | C16: 10 | D16: 3 | E16: 4 | F16: LD101625 | G16: LD071824 | H16: LD102022 | I16: LD071824 | J16: LD101923 | K16: LD102022 | L16: =C16&N16 -> 1010 | M16: =A16 -> 2025-10-17 | N16: 10 | O16: LD101624 | P16: LD101623 | Q16: =F16 -> LD101625 | R16: =Q15 -> LD101525 | S16: =S15 -> LD101025 | T16: =+O16 -> LD101624 | W16: 2025-10-17 | X16: =W16-A16 -> 0 | Y16: LD101624 | Z16: LD101623
A17: 2025-10-20 | B17: 4 | C17: 10 | D17: 3 | E17: 5 | F17: LD101725 | G17: LD071924 | H17: LD011723 | I17: LD071924 | J17: LD102023 | K17: LD102122 | L17: =C17&N17 -> 109 | M17: =A17 -> 2025-10-20 | N17: 9 | O17: LD101724 | P17: LD101723 | Q17: =F17 -> LD101725 | R17: =Q16 -> LD101625 | S17: =S16 -> LD101025 | T17: =+O17 -> LD101724 | W17: 2025-10-20 | X17: =W17-A17 -> 0 | Y17: LD101724 | Z17: LD101723
A18: 2025-10-21 | B18: 4 | C18: 10 | D18: 4 | E18: 1 | F18: LD102025 | G18: LD072224 | H18: LD102422 | I18: LD072224 | J18: LD102323 | K18: LD102422 | L18: =C18&N18 -> 108 | M18: =A18 -> 2025-10-21 | N18: 8 | O18: LD101824 | P18: LD101823 | Q18: =F18 -> LD102025 | R18: =Q17 -> LD101725 | S18: =Q17 -> LD101725 | T18: =+O18 -> LD101824 | W18: 2025-10-21 | X18: =W18-A18 -> 0 | Y18: LD101824 | Z18: LD101823
A19: 2025-10-22 | B19: 4 | C19: 10 | D19: 4 | E19: 2 | F19: LD102125 | G19: LD072324 | H19: LD102522 | I19: LD072324 | J19: LD102423 | K19: LD102522 | L19: =C19&N19 -> 107 | M19: =A19 -> 2025-10-22 | N19: 7 | O19: LD102124 | P19: LD101923 | Q19: =F19 -> LD102125 | R19: =Q18 -> LD102025 | S19: =S18 -> LD101725 | T19: =+O19 -> LD102124 | W19: 2025-10-22 | X19: =W19-A19 -> 0 | Y19: LD102124 | Z19: LD101923
A20: 2025-10-23 | B20: 4 | C20: 10 | D20: 4 | E20: 3 | F20: LD102225 | G20: LD072424 | H20: LD102622 | I20: LD072424 | J20: LD102523 | K20: LD102622 | L20: =C20&N20 -> 106 | M20: =A20 -> 2025-10-23 | N20: 6 | O20: LD102224 | P20: LD102023 | Q20: =F20 -> LD102225 | R20: =Q19 -> LD102125 | S20: =S19 -> LD101725 | T20: =+O20 -> LD102224 | W20: 2025-10-23 | X20: =W20-A20 -> 0 | Y20: LD102224 | Z20: LD102023
A21: 2025-10-24 | B21: 4 | C21: 10 | D21: 4 | E21: 4 | F21: LD102325 | G21: LD072524 | H21: LD102722 | I21: LD072524 | J21: LD102623 | K21: LD102722 | L21: =C21&N21 -> 105 | M21: =A21 -> 2025-10-24 | N21: 5 | O21: LD102324 | P21: LD102323 | Q21: =F21 -> LD102325 | R21: =Q20 -> LD102225 | S21: =S20 -> LD101725 | T21: =+O21 -> LD102324 | W21: 2025-10-24 | X21: =W21-A21 -> 0 | Y21: LD102324 | Z21: LD102323
A22: 2025-10-27 | B22: 4 | C22: 10 | D22: 4 | E22: 5 | F22: LD102425 | G22: LD072624 | H22: LD012423 | I22: LD072624 | J22: LD102723 | K22: LD102822 | L22: =C22&N22 -> 104 | M22: =A22 -> 2025-10-27 | N22: 4 | O22: LD102424 | P22: LD102423 | Q22: =F22 -> LD102425 | R22: =Q21 -> LD102325 | S22: =S21 -> LD101725 | T22: =+O22 -> LD102424 | W22: 2025-10-27 | X22: =W22-A22 -> 0 | Y22: LD102424 | Z22: LD102423
A23: 2025-10-28 | B23: 4 | C23: 10 | D23: 5 | E23: 1 | F23: LD102725 | G23: LD072924 | H23: LD102822 | I23: LD072624 | J23: LD102723 | K23: LD102822 | L23: =C23&N23 -> 103 | M23: =A23 -> 2025-10-28 | N23: 3 | O23: LD102524 | P23: LD102523 | Q23: =F23 -> LD102725 | R23: =Q22 -> LD102425 | S23: =Q22 -> LD102425 | T23: =+O23 -> LD102524 | W23: 2025-10-28 | X23: =W23-A23 -> 0 | Y23: LD102524 | Z23: LD102523
A24: 2025-10-29 | B24: 4 | C24: 10 | D24: 5 | E24: 2 | F24: LD102825 | G24: LD073024 | H24: LD103122 | I24: LD072924 | J24: LD103023 | K24: LD103122 | L24: =C24&N24 -> 102 | M24: =A24 -> 2025-10-29 | N24: 2 | O24: LD102824 | P24: LD102623 | Q24: =F24 -> LD102825 | R24: =Q23 -> LD102725 | S24: =Q22 -> LD102425 | T24: =+O24 -> LD102824 | W24: 2025-10-29 | X24: =W24-A24 -> 0 | Y24: LD102824 | Z24: LD102623
A25: 2025-10-30 | B25: 4 | C25: 10 | D25: 5 | E25: 3 | F25: LD102925 | G25: LD073124 | H25: LD110122 | I25: LD073024 | J25: LD103123 | K25: LD110122 | L25: =C25&N25 -> 101 | M25: =A25 -> 2025-10-30 | N25: 1 | O25: LD102924 | P25: LD102723 | Q25: =F25 -> LD102925 | R25: =Q24 -> LD102825 | S25: =S24 -> LD102425 | T25: =+O25 -> LD102924 | W25: 2025-10-30 | X25: =W25-A25 -> 0 | Y25: LD102924 | Z25: LD102723
A26: 2025-10-31 | B26: 4 | C26: 10 | D26: 5 | E26: 4 | F26: LD103025 | G26: LD080124 | H26: LD110222 | I26: LD073124 | J26: LD110123 | K26: LD110222 | L26: =C26&N26 -> 100 | M26: =A26 -> 2025-10-31 | N26: 0 | O26: LD103024 | P26: LD103023 | Q26: =F26 -> LD103025 | R26: =Q25 -> LD102925 | S26: =S25 -> LD102425 | T26: =+O26 -> LD103024 | W26: 2025-10-31 | X26: =W26-A26 -> 0 | Y26: LD103024 | Z26: LD103023
A27: 2025-11-03 | B27: 4 | C27: 10 | D27: 5 | E27: 5 | F27: LD103125 | G27: LD080224 | H27: LD110322 | I27: LD080124 | J27: LD110223 | K27: LD110322 | L27: =C27&N27 -> 1020 | M27: =A27 -> 2025-11-03 | N27: 20 | O27: LD103124 | P27: LD103123 | Q27: =F27 -> LD103125 | R27: =Q26 -> LD103025 | S27: =S26 -> LD102425 | T27: =+O27 -> LD103124 | W27: 2025-11-03 | X27: =W27-A27 -> 0 | Y27: LD103124 | Z27: LD103123
A28: 2025-11-04 | B28: 4 | C28: 11 | D28: 6 | E28: 1 | F28: LD110325 | G28: LD080524 | H28: LD110422 | I28: LD080224 | J28: LD110323 | K28: LD110422 | L28: =C28&N28 -> 1119 | M28: =A28 -> 2025-11-04 | N28: 19 | O28: LD110424 | P28: LD110323 | Q28: =F28 -> LD110325 | R28: =Q27 -> LD103125 | S28: =Q27 -> LD103125 | T28: =+O28 -> LD110424 | W28: 2025-11-04 | X28: =W28-A28 -> 0 | Y28: LD110424 | Z28: LD110323
A29: 2025-11-05 | B29: 4 | C29: 11 | D29: 6 | E29: 2 | F29: LD110425 | G29: LD080624 | H29: LD110722 | I29: LD080524 | J29: LD110623 | K29: LD110722 | L29: =C29&N29 -> 1118 | M29: =A29 -> 2025-11-05 | N29: 18 | O29: LD110524 | P29: LD110623 | Q29: =F29 -> LD110425 | R29: =Q28 -> LD110325 | S29: =Q27 -> LD103125 | T29: =+O29 -> LD110524 | W29: 2025-11-05 | X29: =W29-A29 -> 0 | Y29: LD110524 | Z29: LD110623
A30: 2025-11-06 | B30: 4 | C30: 11 | D30: 6 | E30: 3 | F30: LD110525 | G30: LD080724 | H30: LD110822 | I30: LD080624 | J30: LD110723 | K30: LD110822 | L30: =C30&N30 -> 1117 | M30: =A30 -> 2025-11-06 | N30: 17 | O30: LD110624 | P30: LD110723 | Q30: =F30 -> LD110525 | R30: =Q29 -> LD110425 | S30: =S29 -> LD103125 | T30: =+O30 -> LD110624 | W30: 2025-11-06 | X30: =W30-A30 -> 0 | Y30: LD110624 | Z30: LD110723
A31: 2025-11-07 | B31: 4 | C31: 11 | D31: 6 | E31: 4 | F31: LD110625 | G31: LD080824 | H31: LD110922 | I31: LD080724 | J31: LD110823 | K31: LD110922 | L31: =C31&N31 -> 1116 | M31: =A31 -> 2025-11-07 | N31: 16 | O31: LD110724 | P31: LD110823 | Q31: =F31 -> LD110625 | R31: =Q30 -> LD110525 | S31: =S30 -> LD103125 | T31: =+O31 -> LD110724 | W31: 2025-11-07 | X31: =W31-A31 -> 0 | Y31: LD110724 | Z31: LD110823
A32: 2025-11-10 | B32: 4 | C32: 11 | D32: 6 | E32: 5 | F32: LD110725 | G32: LD080924 | H32: LD111022 | I32: LD080824 | J32: LD110923 | K32: LD111022 | L32: =C32&N32 -> 1115 | M32: =A32 -> 2025-11-10 | N32: 15 | O32: LD110824 | P32: LD110923 | Q32: =F32 -> LD110725 | R32: =Q31 -> LD110625 | S32: =S31 -> LD103125 | T32: =+O32 -> LD110824 | W32: 2025-11-10 | X32: =W32-A32 -> 0 | Y32: LD110824 | Z32: LD110923
A33: 2025-11-11 | B33: 4 | C33: 11 | D33: 7 | E33: 1 | F33: LD111025 | G33: LD081224 | H33: LD021023 | I33: LD080924 | J33: LD111023 | K33: LD111122 | L33: =C33&N33 -> 1114 | M33: =A33 -> 2025-11-11 | N33: 14 | O33: LD111124 | P33: LD111023 | Q33: =F33 -> LD111025 | R33: =Q32 -> LD110725 | S33: =Q32 -> LD110725 | T33: =+O33 -> LD111124 | W33: 2025-11-11 | X33: =W33-A33 -> 0 | Y33: LD111124 | Z33: LD111023
A34: 2025-11-12 | B34: 4 | C34: 11 | D34: 7 | E34: 2 | F34: LD111125 | G34: LD081324 | H34: LD111422 | I34: LD081224 | J34: LD111323 | K34: LD111422 | L34: =C34&N34 -> 1113 | M34: =A34 -> 2025-11-12 | N34: 13 | O34: LD111224 | P34: LD111323 | Q34: =F34 -> LD111125 | R34: =Q33 -> LD111025 | S34: =S33 -> LD110725 | T34: =+O34 -> LD111224 | W34: 2025-11-12 | X34: =W34-A34 -> 0 | Y34: LD111224 | Z34: LD111323
A35: 2025-11-13 | B35: 4 | C35: 11 | D35: 7 | E35: 3 | F35: LD111225 | G35: LD081424 | H35: LD111522 | I35: LD081324 | J35: LD111423 | K35: LD111522 | L35: =C35&N35 -> 1112 | M35: =A35 -> 2025-11-13 | N35: 12 | O35: LD111324 | P35: LD111423 | Q35: =F35 -> LD111225 | R35: =Q34 -> LD111125 | S35: =S34 -> LD110725 | T35: =+O35 -> LD111324 | W35: 2025-11-13 | X35: =W35-A35 -> 0 | Y35: LD111324 | Z35: LD111423
A36: 2025-11-14 | B36: 4 | C36: 11 | D36: 7 | E36: 4 | F36: LD111325 | G36: LD081524 | H36: LD111622 | I36: LD081424 | J36: LD111523 | K36: LD111622 | L36: =C36&N36 -> 1111 | M36: =A36 -> 2025-11-14 | N36: 11 | O36: LD111424 | P36: LD111523 | Q36: =F36 -> LD111325 | R36: =Q35 -> LD111225 | S36: =S35 -> LD110725 | T36: =+O36 -> LD111424 | W36: 2025-11-14 | X36: =W36-A36 -> 0 | Y36: LD111424 | Z36: LD111523
A37: 2025-11-17 | B37: 4 | C37: 11 | D37: 7 | E37: 5 | F37: LD111425 | G37: LD081624 | H37: LD111722 | I37: LD081524 | J37: LD111623 | K37: LD111722 | L37: =C37&N37 -> 1110 | M37: =A37 -> 2025-11-17 | N37: 10 | O37: LD111524 | P37: LD111623 | Q37: =F37 -> LD111425 | R37: =Q36 -> LD111325 | S37: =S36 -> LD110725 | T37: =+O37 -> LD111524 | W37: 2025-11-17 | X37: =W37-A37 -> 0 | Y37: LD111524 | Z37: LD111623
A38: 2025-11-18 | B38: 4 | C38: 11 | D38: 8 | E38: 1 | F38: LD111725 | G38: LD081924 | H38: LD021723 | I38: LD081624 | J38: LD111723 | K38: LD111822 | L38: =C38&N38 -> 119 | M38: =A38 -> 2025-11-18 | N38: 9 | O38: LD111824 | P38: LD111723 | Q38: =F38 -> LD111725 | R38: =Q37 -> LD111425 | S38: =Q37 -> LD111425 | T38: =+O38 -> LD111824 | W38: 2025-11-18 | X38: =W38-A38 -> 0 | Y38: LD111824 | Z38: LD111723
A39: 2025-11-19 | B39: 4 | C39: 11 | D39: 8 | E39: 2 | F39: LD111825 | G39: LD082024 | H39: LD112122 | I39: LD081924 | J39: LD112023 | K39: LD112122 | L39: =C39&N39 -> 118 | M39: =A39 -> 2025-11-19 | N39: 8 | O39: LD111924 | P39: LD112023 | Q39: =F39 -> LD111825 | R39: =Q38 -> LD111725 | S39: =S38 -> LD111425 | T39: =+O39 -> LD111924 | W39: 2025-11-19 | X39: =W39-A39 -> 0 | Y39: LD111924 | Z39: LD112023
A40: 2025-11-20 | B40: 4 | C40: 11 | D40: 8 | E40: 3 | F40: LD111925 | G40: LD082124 | H40: LD112222 | I40: LD082024 | J40: LD112123 | K40: LD112222 | L40: =C40&N40 -> 117 | M40: =A40 -> 2025-11-20 | N40: 7 | O40: LD112024 | P40: LD112123 | Q40: =F40 -> LD111925 | R40: =Q39 -> LD111825 | S40: =S39 -> LD111425 | T40: =+O40 -> LD112024 | W40: 2025-11-20 | X40: =W40-A40 -> 0 | Y40: LD112024 | Z40: LD112123
A41: 2025-11-21 | B41: 4 | C41: 11 | D41: 8 | E41: 4 | F41: LD112025 | G41: LD082224 | H41: LD112322 | I41: LD082124 | J41: LD112223 | K41: LD112322 | L41: =C41&N41 -> 116 | M41: =A41 -> 2025-11-21 | N41: 6 | O41: LD112124 | P41: LD112223 | Q41: =F41 -> LD112025 | R41: =Q40 -> LD111925 | S41: =S40 -> LD111425 | T41: =+O41 -> LD112124 | W41: 2025-11-21 | X41: =W41-A41 -> 0 | Y41: LD112124 | Z41: LD112223
A42: 2025-11-24 | B42: 4 | C42: 11 | D42: 8 | E42: 5 | F42: LD112125 | G42: LD082324 | H42: LD112422 | I42: LD082224 | J42: LD112323 | K42: LD112422 | L42: =C42&N42 -> 115 | M42: =A42 -> 2025-11-24 | N42: 5 | O42: LD112224 | P42: LD112323 | Q42: =F42 -> LD112125 | R42: =Q41 -> LD112025 | S42: =S41 -> LD111425 | T42: =+O42 -> LD112224 | W42: 2025-11-24 | X42: =W42-A42 -> 0 | Y42: LD112224 | Z42: LD112323
...

Sheet INPUT
A1: CURR YEAR | B1: 25 | D1: TODAY | E1: =TODAY() -> 45975
A2: CURR QTR | B2: 4Q | D2: CD | E2: =VLOOKUP($B$5&$G$6,Ref!$L$7:$T$72,6,0) -> LD111325 | G2: CQ Stream | I2: Consol case MT | J2: BUDcm | K2: PY Consol | L2: AAP2024 | P2: CW Tracks | Q2: WK7 | AH2: Jan | AI2: 1Q
A3: NQ | B3: 1Q | D3: PD | E3: =VLOOKUP($B$5&$G$6,Ref!$L$7:$T$72,7,0) -> LD111225 | G3: 4Q Stream | I3: Consol case QTR | J3: FCTcm | K3: PPY Consol | L3: AAP2023 | P3: PW Tracks | Q3: WK6 | W3: WW | Y3: WW | Z3: W | AA3: WW | AH3: Apr | AI3: 2Q
A4: CURR MTH | B4: NovQTD | C4: FebYTD | D4: PW | E4: =VLOOKUP($B$5&$G$6,Ref!$L$7:$T$72,8,0) -> LD110725 | W4: Americas | Y4: Americas | Z4: AM | AA4: Americas | AH4: Jul | AI4: 3Q
A5: CURR MTH | B5: 11 | D5: PY | E5: =VLOOKUP($B$5&$G$6,Ref!$L$7:$T$72,9,0) -> LD111424 | W5: EMEA | Y5: Europe | Z5: EM | AA5: EMEA | AH5: Oct | AI5: 4Q
E6: PROJECTION | F6: Days to go | G6: 11 | W6: Japan | Y6: Japan | Z6: JN | AA6: Japan | AH6: FebQTD
E7: z | L7: MTH1 | M7: MTH2QTD | N7: CQ | W7: APAC | Y7: AsiaPacific | Z7: AP | AA7: APAC | AH7: MayQTD
E8: CASE PY | F8: =VLOOKUP(G6,INPUT!A20:U41,2,FALSE) -> Ld101624 | I8: updated each month!! --> | K8: CASE PY | L8: 2 | M8: 9 | N8: 16 | AH8: AugQTD
E9: PY FINAL MTH | F9: =VLOOKUP(0,INPUT!A20:U41,2,FALSE) -> Ld103124 | I9: updated each month!! --> | K9: PY FINAL MTH | L9: 2 | M9: 9 | N9: 16 | AH9: NovQTD
E10: PY FINAL QTR | F10: =VLOOKUP(0,INPUT!A20:U41,16,FALSE) -> Ld3Q24Final | G10: =RIGHT(LEFT(F10,4),2) -> 3Q | K10: PY FINAL QTR | L10: 16 | M10: 16 | N10: 16
E11: CASEPPY | F11: =VLOOKUP(G6,INPUT!A20:U41,17,FALSE) -> Ld091423 | I11: updated each month!! --> | K11: CASEPPY | L11: 3 | M11: 10 | N11: 17
E12: PPY FINAL MTH | F12: =VLOOKUP(0,INPUT!A20:U41,17,FALSE) -> Ld3Q23Final | I12: updated each month!! --> | K12: PPY FINAL MTH | L12: 3 | M12: 10 | N12: 17
E13: PPY FINAL QTR | F13: =VLOOKUP(0,INPUT!A20:U41,17,FALSE) -> Ld3Q23Final | G13: =RIGHT(LEFT(F13,4),2) -> 3Q | K13: PPY FINAL QTR | L13: 17 | M13: 17 | N13: 17
A14: =COLUMN() -> 1 | B14: =COLUMN() -> 2 | C14: =COLUMN() -> 3 | D14: =COLUMN() -> 4 | E14: =COLUMN() -> 5 | F14: =COLUMN() -> 6 | G14: =COLUMN() -> 7 | H14: =COLUMN() -> 8 | ... U14: =COLUMN() -> 21
A15: PROJECTION CASES
B16: <-------------------- Month 1 QTD ------------------------> | I16: <-------------------- Month 2 QTD ------------------------> | P16: <-------------------- Month 3 FULL QTR ------------------------>
B17: <-- 2 yr avg --> | D17: <-------------- 4Q Average --------------> | I17: <-- 2 yr avg --> | K17: <-------------- 4Q Average --------------> | P17: <-- 2 yr avg --> | R17: <-------------- 4Q Average -------------->
B18: PY | C18: PY 2 | D18: Prior Qtr | E18: 2 qtrs ago | F18: 3 qtrs ago | G18: 4 qtrs ago | I18: PY | J18: PY 2 | K18: Prior Qtr | L18: 2 qtrs ago | M18: 3 qtrs ago | N18: 4 qtrs ago | P18: PY | Q18: PY 2 | R18: Prior Qtr | S18: 2 qtrs ago | T18: 3 qtrs ago | U18: 4 qtrs ago
A19: Days to Go | B19: 4Q24 | C19: 4Q23 | D19: 3Q25 | E19: 2Q25 | F19: 1Q25 | G19: 4Q24 | I19: 4Q24 | J19: 4Q23 | K19: 3Q25 | L19: 2Q25 | M19: 1Q25 | N19: 4Q24 | P19: 4Q24 | Q19: 4Q23 | R19: 3Q25 | S19: 2Q25 | T19: 1Q25 | U19: 4Q24
A20: 21 | B20: Ld070224 | C20: Ld070223 | D20: Ld040125 | I20: Ld050424 | P20: Ld060124 | Q20: Ld090223
A21: 20 | B21: Ld070324 | C21: Ld070323 | D21: Ld040225 | I21: Ld050524 | J21: Ld080323 | K21: LD050425 | L21: Ld020225 | M21: Ld110324 | N21: Ld080323 | P21: Ld060324 | Q21: Ld090323
A22: 19 | B22: Ld100424 | C22: Ld100423 | D22: Ld070425 | E22: Ld040325 | F22: Ld010625 | G22: Ld100423 | I22: Ld110424 | J22: ld110323 | K22: Ld080425 | L22: LD050525 | M22: Ld020325 | N22: ld110323 | P22: Ld090324 | Q22: Ld090423 | R22: Ld060325 | S22: Ld090425 | T22: Ld120424 | U22: Ld090423
A23: 18 | B23: Ld100724 | C23: Ld100523 | D23: Ld070725 | E23: LD040425 | F23: Ld010725 | G23: Ld100523 | I23: Ld110524 | J23: ld110623 | K23: Ld080525 | L23: LD050625 | M23: Ld020425 | N23: ld110623 | P23: Ld090424 | Q23: Ld090523 | R23: Ld060425 | S23: Ld090525 | T23: Ld120524 | U23: Ld090523
A24: 17 | B24: Ld100824 | C24: Ld100623 | D24: Ld070825 | E24: LD040725 | F24: Ld010825 | G24: Ld100623 | I24: Ld110624 | J24: ld110723 | K24: Ld080625 | L24: LD050725 | M24: Ld020525 | N24: ld110723 | P24: Ld090524 | Q24: Ld090623 | R24: Ld060525 | S24: Ld090625 | T24: Ld120624 | U24: Ld090623
A25: 16 | B25: Ld100924 | C25: Ld100923 | D25: Ld070925 | E25: LD040825 | F25: Ld010925 | G25: Ld100923 | I25: Ld110724 | J25: ld110823 | K25: Ld080725 | L25: LD050825 | M25: Ld020625 | N25: ld110823 | P25: Ld090624 | Q25: Ld090723 | R25: Ld060625 | S25: Ld090725 | T25: Ld120924 | U25: Ld090723
A26: 15 | B26: Ld101024 | C26: Ld101023 | D26: Ld071025 | E26: LD040925 | F26: Ld011025 | G26: Ld101023 | I26: Ld110824 | J26: ld110923 | K26: Ld080825 | L26: LD050925 | M26: Ld020725 | N26: ld110923 | P26: Ld090924 | Q26: Ld090823 | R26: Ld060925 | S26: Ld091025 | T26: Ld121024 | U26: Ld090823
A27: 14 | B27: Ld101124 | C27: Ld101123 | D27: Ld071125 | E27: LD041025 | F27: Ld011325 | G27: Ld101123 | I27: Ld111124 | J27: ld111023 | K27: Ld081125 | L27: LD051225 | M27: Ld021025 | N27: ld111023 | P27: Ld091024 | Q27: Ld091123 | R27: Ld061025 | S27: Ld091125 | T27: Ld121124 | U27: Ld091123
A28: 13 | B28: Ld101424 | C28: Ld101223 | D28: Ld071425 | E28: LD041125 | F28: Ld011425 | G28: Ld101223 | I28: Ld111224 | J28: ld111323 | K28: Ld081225 | L28: LD051325 | M28: Ld021125 | N28: ld111323 | P28: Ld091124 | Q28: Ld091223 | R28: Ld061125 | S28: Ld091225 | T28: Ld121224 | U28: Ld091223
A29: 12 | B29: Ld101524 | C29: Ld101323 | D29: Ld071525 | E29: LD041425 | F29: Ld011525 | G29: Ld101323 | I29: Ld111324 | J29: ld111423 | K29: Ld081325 | L29: LD051425 | M29: Ld021225 | N29: ld111423 | P29: Ld091224 | Q29: Ld091323 | R29: Ld061225 | S29: Ld091325 | T29: Ld121324 | U29: Ld091323
A30: 11 | B30: Ld101624 | C30: Ld101623 | D30: Ld071625 | E30: LD041525 | F30: Ld011625 | G30: Ld101623 | I30: Ld111424 | J30: ld111523 | K30: Ld081425 | L30: LD051525 | M30: Ld021325 | N30: ld111523 | P30: Ld091324 | Q30: Ld091423 | R30: Ld061325 | S30: Ld091425 | T30: Ld121624 | U30: Ld091423
A31: 10 | B31: Ld101724 | C31: Ld101723 | D31: Ld071725 | E31: LD041625 | F31: Ld011725 | G31: Ld101723 | I31: Ld111524 | J31: ld111623 | K31: Ld081525 | L31: LD051625 | M31: Ld021425 | N31: ld111623 | P31: Ld091624 | Q31: Ld091523 | R31: Ld061625 | S31: Ld091725 | T31: Ld121724 | U31: Ld091523
A32: 9 | B32: Ld101824 | C32: Ld101823 | D32: Ld071825 | E32: LD041725 | F32: Ld012025 | G32: Ld101823 | I32: Ld111824 | J32: ld111723 | K32: Ld081825 | L32: LD051925 | M32: Ld021725 | N32: ld111723 | P32: Ld091724 | Q32: Ld091823 | R32: Ld061725 | S32: Ld091825 | T32: Ld121824 | U32: Ld091823
A33: 8 | B33: Ld102124 | C33: Ld101923 | D33: Ld072125 | E33: LD041825 | F33: Ld012125 | G33: Ld101923 | I33: Ld111924 | J33: ld112023 | K33: Ld081925 | L33: LD052025 | M33: Ld021825 | N33: ld112023 | P33: Ld091824 | Q33: Ld091923 | R33: Ld061825 | S33: Ld091925 | T33: Ld121924 | U33: Ld091923
... A41: 0 | B41: Ld103124 | C41: Ld103123 | D41: Ld073125 | E41: LD043025 | F41: Ld013125 | G41: Ld103124 | I41: Ld112924 | J41: ld113023 | K41: Ld082925 | L41: LD053025 | M41: Ld022825 | N41: ld113023 | P41: Ld3Q24Final | Q41: Ld3Q23Final | R41: LD2Q25 Final | S41: Ld1Q25Final | T41: Ld4Q24Final | U41: Ld3Q23Final

Sheet WW
Q2: =D9-H9 -> 2837.7679
D3: Console | E3: Console | H3: Load | K3: Load | L3: Load | M3: Load | N3: Load | O3: Load | P3: Console | R3: CW Tracks | T3: PW track | W3: Trans | Y3: Annuity
D4: F | E4: T | H4: E | K4: T | L4: F | M4: G | P4: G | R4: E | T4: G | W4: F | Y4: E
C5: GEO: | D5: bud23 | E5: act22 | H5: CD1Q | J5: PY1Q | L5: PD1Q | M5: PW1Q | W5: CY1Q
C6: WW | D6: Budget | H6: FIRM LOAD (HW) | W6: NonHW | AD6: TOTAL LOAD
C7: Full QTR | D7: =INPUT!$B$2 -> 4Q | F7: YtY | H7: Load | I7: o/w shipped | J7: PY | K7: YtY | L7: PD | M7: PW | N7: DtD | O7: WtW | P7: HW Budget | Q7: B/(W) to Budget | R7: =CONCATENATE("Track ", +'Tracks Pull'!E12) -> Track WK7 | S7: B/(W) Track | T7: =+'Tracks Pull'!G12 -> WtW | U7: WtW B/(W) Track | W7: SW Tx Firm | X7: SW Tx ToGo | Y7: ISC Annuity | Z7: NonHW Trans+Annuity | AA7: NonHW Budget | AB7: B/(W) Bgt | AD7: FIRM + NonHW | AE7: YtY | AF7: B/(W) to Budget
A9: BRAND | C9: Systems w/o TPS | D9: =SUM(D10:D15) -> 3286.3575 | E9: =SUM(E10:E15) -> 2838.1265 | F9: =+D9/E9-1 -> 0.15793201 | H9: =SUM(H10:H15) -> 448.58962 | I9: =SUM(I10:I15) -> 256.76876 | J9: =SUM(J10:J15) -> 386.76836 | K9: =H9/J9-1 -> 0.15984053 | L9: =SUM(L10:L15) -> 416.87528 | M9: =SUM(M10:M15) -> 361.87233 | N9: =SUM(N10:N15) -> 31.714339 | O9: =SUM(O10:O15) -> 86.71729 | P9: =SUM(P10:P15) -> 2715.9684 | Q9: =SUM(Q10:Q15) -> -2267.3788 | R9: =SUM(R10:R15) -> 674.61809 | S9: =SUM(S10:S15) -> -217.51703 | ... U9: =SUM(U10:U15) -> -41.418297 | W9: =SUM(W10:W15) -> 15.083014 | X9: =SUM(X10:X15) -> 157.72682 | Y9: =SUM(Y10:Y14) -> 408.405 | Z9: =SUM(Z10:Z14) -> 581.21483 | AA9: =SUM(AA10:AA15) -> 570.3891 | AB9: =SUM(AB10:AB15) -> 10.825731 | AD9: =SUM(AD10:AD14) -> 1029.8044 | AE9: =AD9/E9-1 -> -0.63715343 | AF9: =SUM(AF10:AF15) -> -2256.5531
A10: 26 | C10: Traditional z | D10: =SUMIFS('Consol Pull'!$F:$F,'Consol Pull'!$A:$A,$A10,'Consol Pull'!$B:$B,$C$6) -> 1670.7777 | E10: =SUMIFS('Consol Pull'!$T:$T,'Consol Pull'!$A:$A,$A10,'Consol Pull'!$B:$B,$C$6) -> 1223.6108 | F10: =+D10/E10-1 -> 0.3654486 | H10: =SUMIFS('FIRM Load Pull'!$E:$E,'FIRM Load Pull'!$A:$A,$A10,'FIRM Load Pull'!$B:$B,$C$6) -> 129.49898 | I10: =SUMIFS('Ship Load Pull'!$E:$E,'Ship Load Pull'!$A:$A,$A10,'Ship Load Pull'!$B:$B,$C$6) -> 34.804885 | J10: =SUMIFS('FIRM Load Pull'!$Q:$Q,'FIRM Load Pull'!$A:$A,$A10,'FIRM Load Pull'!$B:$B,$C$6) -> 64.110296 | K10: =H10/J10-1 -> 1.0199404 | L10: =SUMIFS('FIRM Load Pull'!$F:$F,'FIRM Load Pull'!$A:$A,$A10,'FIRM Load Pull'!$B:$B,$C$6) -> 109.46743 | M10: =SUMIFS('FIRM Load Pull'!$G:$G,'FIRM Load Pull'!$A:$A,$A10,'FIRM Load Pull'!$B:$B,$C$6) -> 74.14456 | N10: =H10-L10 -> 20.031546 | O10: =+H10-M10 -> 55.354417 | P10: =SUMIFS('Consol Pull'!$G:$G,'Consol Pull'!$A:$A,$A10,'Consol Pull'!$B:$B,$C$6) -> 1440.3421 | Q10: =H10-P10 -> -1310.8432 | R10: =SUMIFS('Tracks Pull'!$E:$E,'Tracks Pull'!$A:$A,$A10,'Tracks Pull'!$B:$B,$C$6) -> 78.144301 | S10: =H10-R10 -> 51.354676 | T10: =SUMIFS('Tracks Pull'!$G:$G,'Tracks Pull'!$A:$A,$A10,'Tracks Pull'!$B:$B,$C$6) -> 6.2485135 | U10: =O10-T10 -> 49.105904 | W10: =SUMIFS('Stream Pull'!G:G,'Stream Pull'!A:A,$A$10,'Stream Pull'!B:B,$C$6) -> 1.0072507 | X10: =SUMIFS('Stream Pull'!H:H,'Stream Pull'!A:A,$A$10,'Stream Pull'!B:B,$C$6) -> 58.941317 | Y10: =SUMIFS('Stream Pull'!M:M,'Stream Pull'!A:A,$A$10,'Stream Pull'!B:B,$C$6) -> 249.32861 | Z10: =SUM(W10:Y10) -> 309.27718 | AA10: =D10-P10 -> 230.43557 | AB10: =Z10-AA10 -> 78.841612 | AD10: =H10+Z10 -> 438.77616 | AE10: =AD10/E10-1 -> -0.64140873 | AF10: =AD10-D10 -> -1232.0015
A11: Power | C11: Power HW | D11: =SUMIFS('Consol Pull'!$F:$F,'Consol Pull'!$A:$A,$A11,'Consol Pull'!$B:$B,$C$6) -> 705.49744 | E11: =SUMIFS('Consol Pull'!$T:$T,'Consol Pull'!$A:$A,$A11,'Consol Pull'!$B:$B,$C$6) -> 628.39572 | F11: =+D11/E11-1 -> 0.12269612 | H11: =SUMIFS('FIRM Load Pull'!$E:$E,'FIRM Load Pull'!$A:$A,$A11,'FIRM Load Pull'!$B:$B,$C$6) -> 79.56673 | I11: =SUMIFS('Ship Load Pull'!$E:$E,'Ship Load Pull'!$A:$A,$A11,'Ship Load Pull'!$B:$B,$C$6) -> 62.466535 | J11: =SUMIFS('FIRM Load Pull'!$Q:$Q,'FIRM Load Pull'!$A:$A,$A11,'FIRM Load Pull'!$B:$B,$C$6) -> 94.516456 | K11: =H11/J11-1 -> -0.15817061 | L11: =SUMIFS('FIRM Load Pull'!$F:$F,'FIRM Load Pull'!$A:$A,$A11,'FIRM Load Pull'!$B:$B,$C$6) -> 77.039396 | M11: =SUMIFS('FIRM Load Pull'!$G:$G,'FIRM Load Pull'!$A:$A,$A11,'FIRM Load Pull'!$B:$B,$C$6) -> 68.131159 | N11: =H11-L11 -> 2.527334 | O11: =+H11-M11 -> 11.435571 | P11: =SUMIFS('Consol Pull'!$G:$G,'Consol Pull'!$A:$A,$A11,'Consol Pull'!$B:$B,$C$6) -> 487.89249 | Q11: =H11-P11 -> -408.32576 | R11: =SUMIFS('Tracks Pull'!$E:$E,'Tracks Pull'!$A:$A,$A11,'Tracks Pull'!$B:$B,$C$6) -> 174.74552 | S11: =H11-R11 -> -95.178792 | T11: =SUMIFS('Tracks Pull'!$G:$G,'Tracks Pull'!$A:$A,$A11,'Tracks Pull'!$B:$B,$C$6) -> 39.714158 | U11: =O11-T11 -> -28.278587 | W11: =SUMIFS('Stream Pull'!G:G,'Stream Pull'!A:A,$A$11,'Stream Pull'!B:B,$C$6) -> 14.19578 | X11: =SUMIFS('Stream Pull'!H:H,'Stream Pull'!A:A,$A$11,'Stream Pull'!B:B,$C$6) -> 58.905516 | Y11: =SUMIFS('Stream Pull'!M:M,'Stream Pull'!A:A,$A$11,'Stream Pull'!B:B,$C$6) -> 122.24172 | Z11: =SUM(W11:Y11) -> 195.34302 | AA11: =D11-P11 -> 217.60495 | AB11: =Z11-AA11 -> -22.261933 | AD11: =H11+Z11 -> 274.90975 | AE11: =AD11/E11-1 -> -0.56252129 | AF11: =AD11-D11 -> -430.58769
A12: Storage | C12: Storage HW | D12: =SUMIFS('Consol Pull'!$F:$F,'Consol Pull'!$A:$A,$A12,'Consol Pull'!$B:$B,$C$6) -> 836.85793 | E12: =SUMIFS('Consol Pull'!$T:$T,'Consol Pull'!$A:$A,$A12,'Consol Pull'!$B:$B,$C$6) -> 938.76306 | F12: =+D12/E12-1 -> -0.10855255 | H12: =SUMIFS('FIRM Load Pull'!$E:$E,'FIRM Load Pull'!$A:$A,$A12,'FIRM Load Pull'!$B:$B,$C$6) -> 233.99971 | I12: =SUMIFS('Ship Load Pull'!$E:$E,'Ship Load Pull'!$A:$A,$A12,'Ship Load Pull'!$B:$B,$C$6) -> 159.49734 | J12: =SUMIFS('FIRM Load Pull'!$Q:$Q,'FIRM Load Pull'!$A:$A,$A12,'FIRM Load Pull'!$B:$B,$C$6) -> 211.7155 | K12: =H12/J12-1 -> 0.10525547 | L12: =SUMIFS('FIRM Load Pull'!$F:$F,'FIRM Load Pull'!$A:$A,$A12,'FIRM Load Pull'!$B:$B,$C$6) -> 224.84425 | M12: =SUMIFS('FIRM Load Pull'!$G:$G,'FIRM Load Pull'!$A:$A,$A12,'FIRM Load Pull'!$B:$B,$C$6) -> 214.07241 | N12: =H12-L12 -> 9.1554589 | O12: =+H12-M12 -> 19.927302 | P12: =SUMIFS('Consol Pull'!$G:$G,'Consol Pull'!$A:$A,$A12,'Consol Pull'!$B:$B,$C$6) -> 815.63814 | Q12: =H12-P12 -> -581.63843 | R12: =SUMIFS('Tracks Pull'!$E:$E,'Tracks Pull'!$A:$A,$A12,'Tracks Pull'!$B:$B,$C$6) -> 407.69262 | S12: =H12-R12 -> -173.69291 | T12: =SUMIFS('Tracks Pull'!$G:$G,'Tracks Pull'!$A:$A,$A12,'Tracks Pull'!$B:$B,$C$6) -> 82.172916 | U12: =O12-T12 -> -62.245614 | W12: =SUMIFS('Stream Pull'!G:G,'Stream Pull'!A:A,$A$12,'Stream Pull'!B:B,$C$6) -> -0.1200171 | X12: =SUMIFS('Stream Pull'!F:F,'Stream Pull'!A:A,$A$12,'Stream Pull'!B:B,$C$6) -> 39.879983 | Y12: =SUMIFS('Stream Pull'!M:M,'Stream Pull'!A:A,$A$12,'Stream Pull'!B:B,$C$6) -> 20.334665 | Z12: =SUM(W12:Y12) -> 60.09463 | AA12: =D12-P12 -> 21.219791 | AB12: =Z12-AA12 -> 38.87484 | AD12: =H12+Z12 -> 294.09434 | AE12: =AD12/E12-1 -> -0.68672144 | AF12: =AD12-D12 -> -542.76359
A13: Technology | C13: Technology | D13: =SUMIFS('Consol Pull'!$F:$F,'Consol Pull'!$A:$A,$A13,'Consol Pull'!$B:$B,$C$6) -> 18.736803 | E13: =SUMIFS('Consol Pull'!$T:$T,'Consol Pull'!$A:$A,$A13,'Consol Pull'!$B:$B,$C$6) -> 12.229029 | F13: =+D13/E13-1 -> 0.53215791 | P13: =SUMIFS('Consol Pull'!$G:$G,'Consol Pull'!$A:$A,$A13,'Consol Pull'!$B:$B,$C$6) -> 0 | Y13: ='Stream Pull'!E106 -> 16.5 | Z13: =SUM(W13:Y13) -> 16.5 | AA13: =D13-P13 -> 18.736803 | AB13: =Z13-AA13 -> -2.2368029 | AD13: =H13+Z13 -> 16.5 | AE13: =AD13/E13-1 -> 0.34924863 | AF13: =AD13-D13 -> -2.2368029
A14: GARS | C14: GARS | D14: =SUMIFS('Consol Pull'!$F:$F,'Consol Pull'!$A:$A,$A14,'Consol Pull'!$B:$B,$C$6) -> 14.035644 | E14: =SUMIFS('Consol Pull'!$T:$T,'Consol Pull'!$A:$A,$A14,'Consol Pull'!$B:$B,$C$6) -> 20.724697 | F14: =+D14/E14-1 -> -0.32275757 | H14: =SUMIFS('FIRM Load Pull'!$E:$E,'FIRM Load Pull'!$A:$A,$A14,'FIRM Load Pull'!$B:$B,$C$6) -> 5.5241986 | I14: =SUMIFS('Ship Load Pull'!$E:$E,'Ship Load Pull'!$A:$A,$A14,'Ship Load Pull'!$B:$B,$C$6) -> 0 | J14: =SUMIFS('FIRM Load Pull'!$Q:$Q,'FIRM Load Pull'!$A:$A,$A14,'FIRM Load Pull'!$B:$B,$C$6) -> 16.426108 | K14: =H14/J14-1 -> -0.66369401 | L14: =SUMIFS('FIRM Load Pull'!$F:$F,'FIRM Load Pull'!$A:$A,$A14,'FIRM Load Pull'!$B:$B,$C$6) -> 5.5241986 | M14: =SUMIFS('FIRM Load Pull'!$G:$G,'FIRM Load Pull'!$A:$A,$A14,'FIRM Load Pull'!$B:$B,$C$6) -> 5.5241986 | N14: =H14-L14 -> 0 | O14: =+H14-M14 -> 0 | P14: =SUMIFS('Consol Pull'!$G:$G,'Consol Pull'!$A:$A,$A14,'Consol Pull'!$B:$B,$C$6) -> 14.035644 | Q14: =H14-P14 -> -8.5114457 | R14: =+P14 -> 14.035644 | AD14: =H14+Z14 -> 5.5241986 | AE14: =AD14/E14-1 -> -0.73344853 | AF14: =AD14-D14 -> -8.5114457
A15: Division Top | C15: Core HW Top (78, 5R, SP,QS) | D15: =SUMIFS('Consol Pull'!$F:$F,'Consol Pull'!$A:$A,$A15,'Consol Pull'!$B:$B,$C$6) -> 40.451985 | E15: =SUMIFS('Consol Pull'!$T:$T,'Consol Pull'!$A:$A,$A15,'Consol Pull'!$B:$B,$C$6) -> 14.403137 | F15: =+D15/E15-1 -> 1.8085537 | P15: -41.94 | Q15: =H15-P15 -> 41.94 | AA15: =D15-P15 -> 82.391985 | AB15: =Z15-AA15 -> -82.391985 | AF15: =AD15-D15 -> -40.451985
C17: Geography w/o GARS
A18: Systems | C18: Americas | D18: =SUMIFS('Consol Pull'!$F:$F,'Consol Pull'!$A:$A,$A18,'Consol Pull'!$B:$B,$C18) -> 1587.4149 | E18: =SUMIFS('Consol Pull'!$T:$T,'Consol Pull'!$A:$A,$A18,'Consol Pull'!$B:$B,$C18) -> 1228.9529 | F18: =+D18/E18-1 -> 0.2916808 | H18: =SUMIFS('FIRM Load Pull'!$E:$E,'FIRM Load Pull'!$A:$A,$A18,'FIRM Load Pull'!$B:$B,$C18) -> 166.08077 | I18: =SUMIFS('Ship Load Pull'!$E:$E,'Ship Load Pull'!$A:$A,$A18,'Ship Load Pull'!$B:$B,$C18) -> 108.82448 | J18: =SUMIFS('FIRM Load Pull'!$Q:$Q,'FIRM Load Pull'!$A:$A,$A18,'FIRM Load Pull'!$B:$B,$C18) -> 126.8122 | K18: =H18/J18-1 -> 0.30965925 | L18: =SUMIFS('FIRM Load Pull'!$F:$F,'FIRM Load Pull'!$A:$A,$A18,'FIRM Load Pull'!$B:$B,$C18) -> 142.95051 | M18: =SUMIFS('FIRM Load Pull'!$G:$G,'FIRM Load Pull'!$A:$A,$A18,'FIRM Load Pull'!$B:$B,$C18) -> 125.6573 | N18: =H18-L18 -> 23.130262 | O18: =+H18-M18 -> 40.423468 | P18: =SUMIFS('Consol Pull'!$G:$G,'Consol Pull'!$A:$A,$A18,'Consol Pull'!$B:$B,$C18) -> 1363.4667 | Q18: =H18-P18 -> -1197.3859 | R18: =SUMIFS('Tracks Pull'!$E:$E,'Tracks Pull'!$A:$A,$A18,'Tracks Pull'!$B:$B,$C18) -> 250.82298 | S18: =H18-R18 -> -84.742208 | T18: =SUMIFS('Tracks Pull'!$G:$G,'Tracks Pull'!$A:$A,$A18,'Tracks Pull'!$B:$B,$C18) -> 45.494711 | U18: =O18-T18 -> -5.0712433 | W18: =SUMIFS('Stream Pull'!G:G,'Stream Pull'!A:A,$A$18,'Stream Pull'!B:B,$C$18) -> 4.9471084 | X18: =SUMIFS('Stream Pull'!H:H,'Stream Pull'!A:A,$A$18,'Stream Pull'!B:B,$C$18) -> 59.982836 | Y18: =SUMIFS('Stream Pull'!M:M,'Stream Pull'!A:A,$A$18,'Stream Pull'!B:B,$C$18) -> 185.05101 | Z18: =SUM(W18:Y18) -> 249.98096 | AA18: =D18-P18 -> 223.94819 | AB18: =Z18-AA18 -> 26.032764 | AD18: =H18+Z18 -> 416.06173 | AE18: =AD18/E18-1 -> -0.66145023 | AF18: =AD18-D18 -> -1171.3532
A19: Systems | C19: EMEA | D19: =SUMIFS('Consol Pull'!$F:$F,'Consol Pull'!$A:$A,$A19,'Consol Pull'!$B:$B,$C19) -> 1055.6303 | E19: =SUMIFS('Consol Pull'!$T:$T,'Consol Pull'!$A:$A,$A19,'Consol Pull'!$B:$B,$C19) -> 997.63181 | F19: =+D19/E19-1 -> 0.058136175 | H19: =SUMIFS('FIRM Load Pull'!$E:$E,'FIRM Load Pull'!$A:$A,$A19,'FIRM Load Pull'!$B:$B,$C19) -> 173.31338 | I19: =SUMIFS('Ship Load Pull'!$E:$E,'Ship Load Pull'!$A:$A,$A19,'Ship Load Pull'!$B:$B,$C19) -> 94.333667 | J19: =SUMIFS('FIRM Load Pull'!$Q:$Q,'FIRM Load Pull'!$A:$A,$A19,'FIRM Load Pull'!$B:$B,$C19) -> 127.84884 | K19: =H19/J19-1 -> 0.35561173 | L19: =SUMIFS('FIRM Load Pull'!$F:$F,'FIRM Load Pull'!$A:$A,$A19,'FIRM Load Pull'!$B:$B,$C19) -> 165.74581 | M19: =SUMIFS('FIRM Load Pull'!$G:$G,'FIRM Load Pull'!$A:$A,$A19,'FIRM Load Pull'!$B:$B,$C19) -> 137.97891 | N19: =H19-L19 -> 7.5675742 | O19: =+H19-M19 -> 35.33447 | P19: =SUMIFS('Consol Pull'!$G:$G,'Consol Pull'!$A:$A,$A19,'Consol Pull'!$B:$B,$C19) -> 912.1587 | Q19: =H19-P19 -> -738.84531 | R19: =SUMIFS('Tracks Pull'!$E:$E,'Tracks Pull'!$A:$A,$A19,'Tracks Pull'!$B:$B,$C19) -> 254.1138 | S19: =H19-R19 -> -80.800414 | T19: =SUMIFS('Tracks Pull'!$G:$G,'Tracks Pull'!$A:$A,$A19,'Tracks Pull'!$B:$B,$C19) -> 60.192773 | U19: =O19-T19 -> -24.858304 | W19: =SUMIFS('Stream Pull'!G:G,'Stream Pull'!A:A,$A$19,'Stream Pull'!B:B,$C$19) -> 4.0310486 | X19: =SUMIFS('Stream Pull'!H:H,'Stream Pull'!A:A,$A$19,'Stream Pull'!B:B,$C$19) -> 35.227543 | Y19: =SUMIFS('Stream Pull'!M:M,'Stream Pull'!A:A,$A$19,'Stream Pull'!B:B,$C$19) -> 128.72767 | Z19: =SUM(W19:Y19) -> 167.98626 | AA19: =D19-P19 -> 143.47161 | AB19: =Z19-AA19 -> 24.514657 | AD19: =H19+Z19 -> 341.29965 | AE19: =AD19/E19-1 -> -0.65789017 | AF19: =AD19-D19 -> -714.33066
A20: Systems | C20: Japan | D20: =SUMIFS('Consol Pull'!$F:$F,'Consol Pull'!$A:$A,$A20,'Consol Pull'!$B:$B,$C20) -> 219.76523 | E20: =SUMIFS('Consol Pull'!$T:$T,'Consol Pull'!$A:$A,$A20,'Consol Pull'!$B:$B,$C20) -> 226.16138 | F20: =+D20/E20-1 -> -0.02828136 | H20: =SUMIFS('FIRM Load Pull'!$E:$E,'FIRM Load Pull'!$A:$A,$A20,'FIRM Load Pull'!$B:$B,$C20) -> 60.107739 | I20: =SUMIFS('Ship Load Pull'!$E:$E,'Ship Load Pull'!$A:$A,$A20,'Ship Load Pull'!$B:$B,$C20) -> 18.961591 | J20: =SUMIFS('FIRM Load Pull'!$Q:$Q,'FIRM Load Pull'!$A:$A,$A20,'FIRM Load Pull'!$B:$B,$C20) -> 66.651014 | K20: =H20/J20-1 -> -0.098172177 | L20: =SUMIFS('FIRM Load Pull'!$F:$F,'FIRM Load Pull'!$A:$A,$A20,'FIRM Load Pull'!$B:$B,$C20) -> 59.818929 | M20: =SUMIFS('FIRM Load Pull'!$G:$G,'FIRM Load Pull'!$A:$A,$A20,'FIRM Load Pull'!$B:$B,$C20) -> 48.163295 | N20: =H20-L20 -> 0.28880972 | O20: =+H20-M20 -> 11.944444 | P20: =SUMIFS('Consol Pull'!$G:$G,'Consol Pull'!$A:$A,$A20,'Consol Pull'!$B:$B,$C20) -> 160.53057 | Q20: =H20-P20 -> -100.42283 | R20: =SUMIFS('Tracks Pull'!$E:$E,'Tracks Pull'!$A:$A,$A20,'Tracks Pull'!$B:$B,$C20) -> 60.275722 | S20: =H20-R20 -> -0.16798272 | T20: =SUMIFS('Tracks Pull'!$G:$G,'Tracks Pull'!$A:$A,$A20,'Tracks Pull'!$B:$B,$C20) -> 8.0057104 | U20: =O20-T20 -> 3.9387339 | W20: =SUMIFS('Stream Pull'!G:G,'Stream Pull'!A:A,$A$20,'Stream Pull'!B:B,$C$20) -> 3.4392913 | X20: =SUMIFS('Stream Pull'!H:H,'Stream Pull'!A:A,$A$20,'Stream Pull'!B:B,$C$20) -> 6.0735674 | Y20: =SUMIFS('Stream Pull'!M:M,'Stream Pull'!A:A,$A$20,'Stream Pull'!B:B,$C$20) -> 46.623967 | Z20: =SUM(W20:Y20) -> 56.136826 | AA20: =D20-P20 -> 59.234663 | AB20: =Z20-AA20 -> -3.0978372 | AD20: =H20+Z20 -> 116.24456 | AE20: =AD20/E20-1 -> -0.48601055 | AF20: =AD20-D20 -> -103.52067
A21: Systems | C21: APAC | D21: =SUMIFS('Consol Pull'!$F:$F,'Consol Pull'!$A:$A,$A21,'Consol Pull'!$B:$B,$C21) -> 310.08179 | E21: =SUMIFS('Consol Pull'!$T:$T,'Consol Pull'!$A:$A,$A21,'Consol Pull'!$B:$B,$C21) -> 293.28613 | F21: =+D21/E21-1 -> 0.057267152 | H21: =SUMIFS('FIRM Load Pull'!$E:$E,'FIRM Load Pull'!$A:$A,$A21,'FIRM Load Pull'!$B:$B,$C21) -> 43.563528 | I21: =SUMIFS('Ship Load Pull'!$E:$E,'Ship Load Pull'!$A:$A,$A21,'Ship Load Pull'!$B:$B,$C21) -> 34.649021 | J21: =SUMIFS('FIRM Load Pull'!$Q:$Q,'FIRM Load Pull'!$A:$A,$A21,'FIRM Load Pull'!$B:$B,$C21) -> 49.030198 | K21: =H21/J21-1 -> -0.11149597 | L21: =SUMIFS('FIRM Load Pull'!$F:$F,'FIRM Load Pull'!$A:$A,$A21,'FIRM Load Pull'!$B:$B,$C21) -> 42.835836 | M21: =SUMIFS('FIRM Load Pull'!$G:$G,'FIRM Load Pull'!$A:$A,$A21,'FIRM Load Pull'!$B:$B,$C21) -> 44.54862 | N21: =H21-L21 -> 0.72769289 | O21: =+H21-M21 -> -0.9850915 | P21: =SUMIFS('Consol Pull'!$G:$G,'Consol Pull'!$A:$A,$A21,'Consol Pull'!$B:$B,$C21) -> 265.77664 | Q21: =H21-P21 -> -222.21311 | R21: =SUMIFS('Tracks Pull'!$E:$E,'Tracks Pull'!$A:$A,$A21,'Tracks Pull'!$B:$B,$C21) -> 95.36995 | S21: =H21-R21 -> -51.806421 | T21: =SUMIFS('Tracks Pull'!$G:$G,'Tracks Pull'!$A:$A,$A21,'Tracks Pull'!$B:$B,$C21) -> 14.442393 | U21: =O21-T21 -> -15.427484 | W21: =SUMIFS('Stream Pull'!G:G,'Stream Pull'!A:A,$A$21,'Stream Pull'!B:B,$C$21) -> 2.6655652 | X21: =SUMIFS('Stream Pull'!H:H,'Stream Pull'!A:A,$A$21,'Stream Pull'!B:B,$C$21) -> 16.562886 | Y21: =SUMIFS('Stream Pull'!M:M,'Stream Pull'!A:A,$A$21,'Stream Pull'!B:B,$C$21) -> 31.50235 | Z21: =SUM(W21:Y21) -> 50.730801 | AA21: =D21-P21 -> 44.305156 | AB21: =Z21-AA21 -> 6.4256452 | AD21: =H21+Z21 -> 94.29433 | AE21: =AD21/E21-1 -> -0.67849032 | AF21: =AD21-D21 -> -215.78746
A22: Systems | C22: WW Top | D22: =SUMIFS('Consol Pull'!$F:$F,'Consol Pull'!$A:$A,"Systems",'Consol Pull'!$B:$B,"WW",'Consol Pull'!$D:$D,"9op")+D14-'Consol Pull'!F110 -SUMIFS('Consol Pull'!$F:$F,'Consol Pull'!$A:$A,"Systems",'Consol Pull'!$B:$B,"Sum of Geos",'Consol Pull'!$D:$D,"9op") +SUMIFS('Consol Pull'!$F:$F,'Consol Pull'!$A:$A,"M&D OEM",'Consol Pull'!$B:$B,"Sum of Geos") +SUMIFS('Consol Pull'!$F:$F,'Consol Pull'!$A:$A,"Storage OEM",'Consol Pull'!$B:$B,"TOP") +SUM(D13,D15) -> 113.46528 | E22: =SUMIFS('Consol Pull'!$T:$T,'Consol Pull'!$A:$A,"Systems",'Consol Pull'!$B:$B,"WW",'Consol Pull'!$D:$D,"9op") -SUMIFS('Consol Pull'!$T:$T,'Consol Pull'!$A:$A,"Systems",'Consol Pull'!$B:$B,"Sum of Geos",'Consol Pull'!$D:$D,"9op") +SUMIFS('Consol Pull'!$T:$T,'Consol Pull'!$A:$A,"M&D OEM",'Consol Pull'!$B:$B,"Sum of Geos") +SUMIFS('Consol Pull'!$T:$T,'Consol Pull'!$A:$A,"Storage OEM",'Consol Pull'!$B:$B,"TOP")+12.74 +SUM(E13)+E14 -> 92.097483 | F22: =+D22/E22-1 -> 0.23201282 | H22: =+H14 -> 5.5241986 | J22: =SUMIFS('FIRM Load Pull'!$Q:$Q,'FIRM Load Pull'!$A:$A,"GARS",'FIRM Load Pull'!$B:$B,$C$6) -> 16.426108 | L22: =+L14 -> 5.5241986 | M22: =+M14 -> 5.5241986 | N22: =H22-L22 -> 0 | O22: =+H22-M22 -> 0 | P22: =+P14 -> 14.035644 | Q22: =H22-P22 -> -8.5114457 | R22: =R14 -> 14.035644 | W22: =SUMIFS('Stream Pull'!F:F,'Stream Pull'!A:A,$A$22,'Stream Pull'!B:B,$C$22) -> 0 | X22: =X12 -> 39.879983 | Y22: ='Stream Pull'!M106 -> 16.5 | Z22: =SUM(W22:Y22) -> 56.379983 | AA22: =D22-P22 -> 99.429636 | AB22: =Z22-AA22 -> -43.049653 | AD22: =H22+Z22 -> 61.904181 | AE22: =AD22/E22-1 -> -0.32784068 | AF22: =AD22-D22 -> -51.561099
C23: check | D23: =D9-SUM(D18:D22) -> 0 | E23: =E9-SUM(E18:E22) -> -0.00325532 | H23: =H9-SUM(H18:H22) -> 0 | I23: =I9-SUM(I18:I22) -> 0 | J23: =J9-SUM(J18:J22) -> 0 | L23: =L9-SUM(L18:L22) -> 0 | M23: =M9-SUM(M18:M22) -> 0 | N23: =N9-SUM(N18:N22) -> -4.2632564e-14 | O23: =O9-SUM(O18:O22) -> 0 | P23: =P9-SUM(P18:P22) -> 0.00015558617 | Q23: =Q9-SUM(Q18:Q22) -> -0.00015558617 | R23: =R9-SUM(R18:R22) -> 0 | S23: =S9-SUM(S18:S22) -> -3.6948222e-13 | ... U23: =U9-SUM(U18:U22) -> 0 | W23: =W9-SUM(W18:W22) -> 0 | X23: =X9-SUM(X18:X22) -> 0 | Y23: =Y9-SUM(Y18:Y22) -> 0 | Z23: =Z9-SUM(Z18:Z22) -> 0 | AA23: =AA9-SUM(AA18:AA22) -> -0.00015558617 | AB23: =AB9-SUM(AB18:AB22) -> 0.00015558617 | AD23: =AD9-SUM(AD18:AD22) -> 0 | AF23: =AF9-SUM(AF18:AF22) -> 0
C24: o/w GARS, Techn., CoreHW top | D24: =+SUM(D13:D14,D15) -> 73.224432 | E24: =+SUM(E13:E14) -> 32.953726
A25: Systems | B25: Top | C25: o/w Systems OEM | D25: =SUMIFS('Consol Pull'!$F:$F,'Consol Pull'!$A:$A,$A25,'Consol Pull'!$B:$B,$B25) -> 41.940156 | E25: =SUMIFS('Consol Pull'!$T:$T,'Consol Pull'!$A:$A,$A25,'Consol Pull'!$B:$B,$B25) -> 29.928714
A26: Systems | B26: GEO Elims | C26: GEO Elims | D26: =SUMIFS('Consol Pull'!$F:$F,'Consol Pull'!$A:$A,$A26,'Consol Pull'!$B:$B,$B26) -> 0 | E26: =SUMIFS('Consol Pull'!$T:$T,'Consol Pull'!$A:$A,$A26,'Consol Pull'!$B:$B,$B26) -> -10.515255
A27: Storage OEM | B27: Top | C27: Storage OEM (2B) | D27: =SUMIFS('Consol Pull'!$F:$F,'Consol Pull'!$A:$A,$A27,'Consol Pull'!$B:$B,$B27) -> 0 | E27: =SUMIFS('Consol Pull'!$T:$T,'Consol Pull'!$A:$A,$A27,'Consol Pull'!$B:$B,$B27) -> 16.733294
A28: M&D OEM | B28: Sum of Geos | C28: Storage OEM TOP (M&D) | D28: =+SUMIFS('Consol Pull'!$F:$F,'Consol Pull'!$A:$A,"M&D OEM",'Consol Pull'!$B:$B,"Sum of Geos") -> 0 | E28: =+SUMIFS('Consol Pull'!$T:$T,'Consol Pull'!$A:$A,"M&D OEM",'Consol Pull'!$B:$B,"Sum of Geos") -> 10.257005
C29: Other | D29: =+D22-D24-D25-D26-D27-D28 -> -1.6993068 | E29: =+E22-E24-E25-E26-E27-E28 -> 12.74
D45: M | E45: aa | H45: H | J45: R | L45: I | M45: J | P45: N | W45: P | Y45: I
C46: WW | D46: Budget | H46: FIRM LOAD (HW) | W46: NonHW | AD46: TOTAL LOAD
C47: QTD | D47: =INPUT!$B$4 -> NovQTD | F47: YtY | H47: Load | I47: o/w shipped | J47: PY | K47: YtY | L47: PD1Q | M47: PW1Q | N47: DtD | O47: WtW | P47: HW Budget | Q47: B/(W) to Budget | R47: =CONCATENATE("Track ", +'Tracks Pull'!E12) -> Track WK7 | S47: B/(W) Track | T47: =+'Tracks Pull'!G12 -> WtW | U47: WtW B/(W) Track | W47: SW Tx Firm | X47: SW Tx ToGo | Y47: ISC Annuity | Z47: NonHW Trans+Annuity | AA47: NonHW Budget | AB47: B/(W) Bgt | AD47: FIRM + NonHW | AE47: YtY | AF47: B/(W) to Budget
C49: Systems w/o TPS | D49: =SUM(D50:D55) -> 622.38845 | E49: =SUM(E50:E55) -> 635.99271 | F49: =+D49/E49-1 -> -0.021390594 | H49: =SUM(H50:H55) -> 326.86944 | I49: =SUM(I50:I55) -> 255.74594 | J49: =SUM(J50:J55) -> 211.4149 | K49: =H49/J49-1 -> 0.54610409 | L49: =SUM(L50:L55) -> 304.00238 | M49: =SUM(M50:M55) -> 301.65466 | N49: =SUM(N50:N55) -> 22.867062 | O49: =SUM(O50:O55) -> 25.214784 | P49: =SUM(P50:P55) -> 329.3816 | Q49: =SUM(Q50:Q55) -> -2.5121556 | R49: =SUM(R50:R55) -> 666.08143 | S49: =SUM(S50:S54) -> -339.21199 | T49: =SUM(T50:T55) -> 128.13559 | U49: =SUM(U50:U55) -> -102.9208 | W49: =SUM(W50:W54) -> 15.083014 | X49: =SUM(X50:X54) -> 157.72682 | Y49: =SUM(Y50:Y54) -> 259.95653 | Z49: =SUM(Z50:Z54) -> 432.76636 | AA49: =SUM(AA50:AA55) -> 286.77831 | AB49: =SUM(AB50:AB55) -> 145.98805 | AD49: =SUM(AD50:AD55) -> 759.6358 | AE49: =AD49/E49-1 -> 0.1944096 | AF49: =SUM(AF50:AF55) -> 143.47589
A50: 26 | C50: Traditional z | D50: =SUMIFS('Consol Pull'!$M:$M,'Consol Pull'!$A:$A,$A50,'Consol Pull'!$B:$B,$C$6) -> 214.34423 | E50: =SUMIFS('Consol Pull'!$AA:$AA,'Consol Pull'!$A:$A,$A50,'Consol Pull'!$B:$B,$C$6) -> 223.94316 | F50: =+D50/E50-1 -> -0.042863277 | H50: =SUMIFS('FIRM Load Pull'!$K:$K,'FIRM Load Pull'!$A:$A,$A50,'FIRM Load Pull'!$B:$B,$C$6) -> 61.932788 | I50: =SUMIFS('Ship Load Pull'!$H:$H,'Ship Load Pull'!$A:$A,$A50,'Ship Load Pull'!$B:$B,$C6) -> 34.231828 | J50: =SUMIFS('FIRM Load Pull'!$O:$O,'FIRM Load Pull'!$A:$A,$A50,'FIRM Load Pull'!$B:$B,$C$6) -> 40.810043 | K50: =H50/J50-1 -> 0.51758691 | L50: =SUMIFS('FIRM Load Pull'!$L:$L,'FIRM Load Pull'!$A:$A,$A50,'FIRM Load Pull'!$B:$B,$C$6) -> 41.901241 | M50: =SUMIFS('FIRM Load Pull'!$M:$M,'FIRM Load Pull'!$A:$A,$A50,'FIRM Load Pull'!$B:$B,$C$6) -> 33.812883 | N50: =H50-L50 -> 20.031546 | O50: =+H50-M50 -> 28.119905 | P50: =SUMIFS('Consol Pull'!$N:$N,'Consol Pull'!$A:$A,$A50,'Consol Pull'!$B:$B,$C$6) -> 65.657107 | Q50: =H50-P50 -> -3.7243196 | R50: =SUMIFS('Tracks Pull'!$E:$E,'Tracks Pull'!$A:$A,$A50,'Tracks Pull'!$B:$B,$C$6) -> 78.144301 | S50: =H50-R50 -> -16.211514 | T50: =SUMIFS('Tracks Pull'!$G:$G,'Tracks Pull'!$A:$A,$A50,'Tracks Pull'!$B:$B,$C$6) -> 6.2485135 | U50: =O50-T50 -> 21.871391 | W50: =SUMIFS('Stream Pull'!O:O,'Stream Pull'!A:A,$A$50,'Stream Pull'!B:B,$C$6) -> 1.0072507 | X50: =SUMIFS('Stream Pull'!P:P,'Stream Pull'!A:A,$A$50,'Stream Pull'!B:B,$C$6) -> 58.941317 | Y50: =SUMIFS('Stream Pull'!Q:Q,'Stream Pull'!A:A,$A$50,'Stream Pull'!B:B,$C$6) -> 157.03372 | Z50: =SUM(W50:Y50) -> 216.98229 | AA50: =D50-P50 -> 148.68712 | AB50: =Z50-AA50 -> 68.295167 | AD50: =H50+Z50 -> 278.91507 | AE50: =AD50/E50-1 -> 0.24547259 | AF50: =AD50-D50 -> 64.570847
A51: Power | C51: Power HW | D51: =SUMIFS('Consol Pull'!$M:$M,'Consol Pull'!$A:$A,$A51,'Consol Pull'!$B:$B,$C$6) -> 191.71786 | E51: =SUMIFS('Consol Pull'!$AA:$AA,'Consol Pull'!$A:$A,$A51,'Consol Pull'!$B:$B,$C$6) -> 206.01132 | F51: =+D51/E51-1 -> -0.06938192 | H51: =SUMIFS('FIRM Load Pull'!$K:$K,'FIRM Load Pull'!$A:$A,$A51,'FIRM Load Pull'!$B:$B,$C$6) -> 67.451094 | I51: =SUMIFS('Ship Load Pull'!$H:$H,'Ship Load Pull'!$A:$A,$A51,'Ship Load Pull'!$B:$B,$C6) -> 62.466535 | J51: =SUMIFS('FIRM Load Pull'!$O:$O,'FIRM Load Pull'!$A:$A,$A51,'FIRM Load Pull'!$B:$B,$C$6) -> 57.055421 | K51: =H51/J51-1 -> 0.18220308 | L51: =SUMIFS('FIRM Load Pull'!$L:$L,'FIRM Load Pull'!$A:$A,$A51,'FIRM Load Pull'!$B:$B,$C$6) -> 67.082304 | M51: =SUMIFS('FIRM Load Pull'!$M:$M,'FIRM Load Pull'!$A:$A,$A51,'FIRM Load Pull'!$B:$B,$C$6) -> 64.228395 | N51: =H51-L51 -> 0.36879033 | O51: =+H51-M51 -> 3.2226993 | P51: =SUMIFS('Consol Pull'!$N:$N,'Consol Pull'!$A:$A,$A51,'Consol Pull'!$B:$B,$C$6) -> 90.548501 | Q51: =H51-P51 -> -23.097407 | R51: =SUMIFS('Tracks Pull'!$E:$E,'Tracks Pull'!$A:$A,$A51,'Tracks Pull'!$B:$B,$C$6) -> 174.74552 | S51: =H51-R51 -> -107.29443 | T51: =SUMIFS('Tracks Pull'!$G:$G,'Tracks Pull'!$A:$A,$A51,'Tracks Pull'!$B:$B,$C$6) -> 39.714158 | U51: =O51-T51 -> -36.491459 | W51: =SUMIFS('Stream Pull'!O:O,'Stream Pull'!A:A,$A$51,'Stream Pull'!B:B,$C$6) -> 14.19578 | X51: =SUMIFS('Stream Pull'!P:P,'Stream Pull'!A:A,$A$51,'Stream Pull'!B:B,$C$6) -> 58.905516 | Y51: =SUMIFS('Stream Pull'!Q:Q,'Stream Pull'!A:A,$A$51,'Stream Pull'!B:B,$C$6) -> 80.375683 | Z51: =SUM(W51:Y51) -> 153.47698 | AA51: =D51-P51 -> 101.16936 | AB51: =Z51-AA51 -> 52.307623 | AD51: =H51+Z51 -> 220.92807 | AE51: =AD51/E51-1 -> 0.072407454 | AF51: =AD51-D51 -> 29.210216
A52: Storage | C52: Storage HW | D52: =SUMIFS('Consol Pull'!$M:$M,'Consol Pull'!$A:$A,$A52,'Consol Pull'!$B:$B,$C$6) -> 204.59884 | E52: =SUMIFS('Consol Pull'!$AA:$AA,'Consol Pull'!$A:$A,$A52,'Consol Pull'!$B:$B,$C$6) -> 189.68073 | F52: =+D52/E52-1 -> 0.078648506 | H52: =SUMIFS('FIRM Load Pull'!$K:$K,'FIRM Load Pull'!$A:$A,$A52,'FIRM Load Pull'!$B:$B,$C$6) -> 193.22002 | I52: =SUMIFS('Ship Load Pull'!$H:$H,'Ship Load Pull'!$A:$A,$A52,'Ship Load Pull'!$B:$B,$C6) -> 159.04758 | J52: =SUMIFS('FIRM Load Pull'!$O:$O,'FIRM Load Pull'!$A:$A,$A52,'FIRM Load Pull'!$B:$B,$C$6) -> 103.82561 | K52: =H52/J52-1 -> 0.86100549 | L52: =SUMIFS('FIRM Load Pull'!$L:$L,'FIRM Load Pull'!$A:$A,$A52,'FIRM Load Pull'!$B:$B,$C$6) -> 190.7533 | M52: =SUMIFS('FIRM Load Pull'!$M:$M,'FIRM Load Pull'!$A:$A,$A52,'FIRM Load Pull'!$B:$B,$C$6) -> 199.34784 | N52: =H52-L52 -> 2.4667258 | O52: =+H52-M52 -> -6.1278197 | P52: =SUMIFS('Consol Pull'!$N:$N,'Consol Pull'!$A:$A,"Storage",'Consol Pull'!$B:$B,"Sum of Geos",'Consol Pull'!$D:$D,"9op") -> 167.677 | Q52: =H52-P52 -> 25.543021 | R52: =SUMIFS('Tracks Pull'!$E:$E,'Tracks Pull'!$A:$A,$A52,'Tracks Pull'!$B:$B,$C$6) -> 407.69262 | S52: =H52-R52 -> -214.4726 | T52: =SUMIFS('Tracks Pull'!$G:$G,'Tracks Pull'!$A:$A,$A52,'Tracks Pull'!$B:$B,$C$6) -> 82.172916 | U52: =O52-T52 -> -88.300735 | W52: =SUMIFS('Stream Pull'!O:O,'Stream Pull'!A:A,$A$52,'Stream Pull'!B:B,$C$6) -> -0.1200171 | X52: =SUMIFS('Stream Pull'!F:F,'Stream Pull'!A:A,$A$52,'Stream Pull'!B:B,$C$6) -> 39.879983 | Y52: =SUMIFS('Stream Pull'!Q:Q,'Stream Pull'!A:A,$A$52,'Stream Pull'!B:B,$C$6) -> 12.047126 | Z52: =SUM(W52:Y52) -> 51.807092 | AA52: =D52-P52 -> 36.921835 | AB52: =Z52-AA52 -> 14.885256 | AD52: =H52+Z52 -> 245.02711 | AE52: =AD52/E52-1 -> 0.29178706 | AF52: =AD52-D52 -> 40.428278
A53: Technology | C53: Technology | D53: =SUMIFS('Consol Pull'!$M:$M,'Consol Pull'!$A:$A,$A53,'Consol Pull'!$B:$B,$C$6) -> 0 | E53: =SUMIFS('Consol Pull'!$AA:$AA,'Consol Pull'!$A:$A,$A53,'Consol Pull'!$B:$B,$C$6) -> 7.530785 | F53: =+D53/E53-1 -> -1 | Y53: ='Stream Pull'!N106 -> 10.5 | Z53: =SUM(W53:Y53) -> 10.5 | AA53: =D53-P53 -> 0 | AB53: =Z53-AA53 -> 10.5 | AD53: =H53+Z53 -> 10.5 | AE53: =AD53/E53-1 -> 0.39427695 | AF53: =AD53-D53 -> 10.5
