Workbook
Name startday: '1Q26 '!$L$2
Name startday: '2Q26'!$L$2
Name startday: 'Q1'!$L$2
Name valuevx: 42.314159

Sheet Q1
C1: Quarterly Calendar Template
C2: Year | D2: 2025 | G2: Start Month | H2: 1 | K2: Start Day | L2: 1 | M2: 1:Sun,2:Mon | P2: © 2015 Vertex42 LLC
P3: Quarterly Calendar
C5: 1Q Load Calendar
C7: Date: | D7: =DATE(D2,H2,1) -> 45658
A8: =D7 -> 45658 | C8: Sunday | E8: Monday | G8: Tuesday | I8: Wednesday | K8: Thursday | M8: Friday | O8: Saturday | R8: week
C9: =IF(WEEKDAY($D$7,1)=startday,$D$7,"") | D9: =IFERROR(INDEX(Events!$A:$A,MATCH(C9,Events!$G:$G,0)),"") | E9: =IF(C9="",IF(WEEKDAY($D$7,1)=MOD(startday,7)+1,$D$7,""),C9+1) | F9: =IFERROR(INDEX(Events!$A:$A,MATCH(E9,Events!$G:$G,0)),"") | G9: =IF(E9="",IF(WEEKDAY($D$7,1)=MOD(startday+1,7)+1,$D$7,""),E9+1) | H9: =IFERROR(INDEX(Events!$A:$A,MATCH(G9,Events!$G:$G,0)),"") | I9: =IF(G9="",IF(WEEKDAY($D$7,1)=MOD(startday+2,7)+1,$D$7,""),G9+1) -> 45658 | J9: =IFERROR(INDEX(Events!$A:$A,MATCH(I9,Events!$G:$G,0)),"") -> New Year's Day | K9: =IF(I9="",IF(WEEKDAY($D$7,1)=MOD(startday+3,7)+1,$D$7,""),I9+1) -> 45659 | L9: W1 | M9: =IF(K9="",IF(WEEKDAY($D$7,1)=MOD(startday+4,7)+1,$D$7,""),K9+1) -> 45660 | N9: W2 | O9: =IF(M9="",IF(WEEKDAY($D$7,1)=MOD(startday+5,7)+1,$D$7,""),M9+1) -> 45661 | P9: =IFERROR(INDEX(Events!$A:$A,MATCH(O9,Events!$G:$G,0)),"") | R9: week 1
C10: =IFERROR(INDEX(Events!$A:$A,MATCH(C9,Events!$H:$H,0)),"") | D10: =IFERROR(INDEX(Events!#REF!,MATCH(C10,Events!A:A,0)),"") | E10: =IFERROR(INDEX(Events!$A:$A,MATCH(E9,Events!$H:$H,0)),"") | F10: =IFERROR(INDEX(Events!#REF!,MATCH(E10,Events!C:C,0)),"") | G10: =IFERROR(INDEX(Events!$A:$A,MATCH(G9,Events!$H:$H,0)),"") | H10: =IFERROR(INDEX(Events!#REF!,MATCH(G10,Events!E:E,0)),"") | I10: =IFERROR(INDEX(Events!$A:$A,MATCH(I9,Events!$H:$H,0)),"") | J10: =IFERROR(INDEX(Events!A:A,MATCH(I10,Events!G:G,0)),"") | K10: Final Load | L10: =IFERROR(INDEX(Events!C:C,MATCH(K10,Events!I:I,0)),"") | M10: WW courtesy run | O10: =IFERROR(INDEX(Events!$A:$A,MATCH(O9,Events!$H:$H,0)),"") | P10: =IFERROR(INDEX(Events!G:G,MATCH(O10,Events!K:K,0)),"")
C11: =IFERROR(INDEX(Events!$A:$A,MATCH(C9,Events!$I:$I,0)),"") | E11: =IFERROR(INDEX(Events!$A:$A,MATCH(E9,Events!$I:$I,0)),"") | G11: =IFERROR(INDEX(Events!$A:$A,MATCH(G9,Events!$I:$I,0)),"") | I11: =IFERROR(INDEX(Events!$A:$A,MATCH(I9,Events!$I:$I,0)),"") | M11: =IFERROR(INDEX(Events!$A:$A,MATCH(M9,Events!$I:$I,0)),"") | O11: =IFERROR(INDEX(Events!$A:$A,MATCH(O9,Events!$I:$I,0)),"")
C12: =IFERROR(INDEX(Events!$A:$A,MATCH(C9,Events!$J:$J,0)),"") | E12: =IFERROR(INDEX(Events!$A:$A,MATCH(E9,Events!$J:$J,0)),"") | G12: =IFERROR(INDEX(Events!$A:$A,MATCH(G9,Events!$J:$J,0)),"") | I12: =IFERROR(INDEX(Events!$A:$A,MATCH(I9,Events!$J:$J,0)),"") | K12: Blackout | M12: =IFERROR(INDEX(Events!$A:$A,MATCH(M9,Events!$J:$J,0)),"") | O12: =IFERROR(INDEX(Events!$A:$A,MATCH(O9,Events!$J:$J,0)),"")
C13: =IF(O9="","",IF(MONTH(O9+1)<>MONTH(O9),"",O9+1)) -> 45662 | D13: =IFERROR(INDEX(Events!$A:$A,MATCH(C13,Events!$G:$G,0)),"") | E13: =IF(C13="","",IF(MONTH(C13+1)<>MONTH(C13),"",C13+1)) -> 45663 | F13: W2+ | G13: =IF(E13="","",IF(MONTH(E13+1)<>MONTH(E13),"",E13+1)) -> 45664 | H13: W3 | I13: =IF(G13="","",IF(MONTH(G13+1)<>MONTH(G13),"",G13+1)) -> 45665 | J13: W4 | K13: =IF(I13="","",IF(MONTH(I13+1)<>MONTH(I13),"",I13+1)) -> 45666 | L13: W5 | M13: =IF(K13="","",IF(MONTH(K13+1)<>MONTH(K13),"",K13+1)) -> 45667 | N13: W6 | O13: =IF(M13="","",IF(MONTH(M13+1)<>MONTH(M13),"",M13+1)) -> 45668 | P13: W7 | R13: week 2
C14: =IFERROR(INDEX(Events!$A:$A,MATCH(C13,Events!$H:$H,0)),"") | D14: =IFERROR(INDEX(Events!#REF!,MATCH(C14,Events!A:A,0)),"") | E14: =IFERROR(INDEX(Events!$A:$A,MATCH(E13,Events!$H:$H,0)),"") | F14: =IFERROR(INDEX(Events!#REF!,MATCH(E14,Events!C:C,0)),"") | G14: =IFERROR(INDEX(Events!$A:$A,MATCH(G13,Events!$H:$H,0)),"") | H14: =IFERROR(INDEX(Events!#REF!,MATCH(G14,Events!E:E,0)),"") | I14: =IFERROR(INDEX(Events!$A:$A,MATCH(I13,Events!$H:$H,0)),"") | J14: =IFERROR(INDEX(Events!A:A,MATCH(I14,Events!G:G,0)),"") | K14: Roll to next qtr | L14: =IFERROR(INDEX(Events!C:C,MATCH(K14,Events!I:I,0)),"") | M14: GTN update | N14: =IFERROR(INDEX(Events!E:E,MATCH(M14,Events!#REF!,0)),"") | O14: =IFERROR(INDEX(Events!$A:$A,MATCH(O13,Events!$H:$H,0)),"") | P14: =IFERROR(INDEX(Events!G:G,MATCH(O14,Events!K:K,0)),"")
C15: =IFERROR(INDEX(Events!$A:$A,MATCH(C13,Events!$I:$I,0)),"") | E15: =IFERROR(INDEX(Events!$A:$A,MATCH(E13,Events!$I:$I,0)),"") | G15: =IFERROR(INDEX(Events!$A:$A,MATCH(G13,Events!$I:$I,0)),"") | I15: =IFERROR(INDEX(Events!$A:$A,MATCH(I13,Events!$I:$I,0)),"") | K15: AUR valuation | M15: =IFERROR(INDEX(Events!$A:$A,MATCH(M13,Events!$I:$I,0)),"") | O15: =IFERROR(INDEX(Events!$A:$A,MATCH(O13,Events!$I:$I,0)),"")
C16: =IFERROR(INDEX(Events!$A:$A,MATCH(C13,Events!$J:$J,0)),"") | E16: =IFERROR(INDEX(Events!$A:$A,MATCH(E13,Events!$J:$J,0)),"") | G16: =IFERROR(INDEX(Events!$A:$A,MATCH(G13,Events!$J:$J,0)),"") | I16: =IFERROR(INDEX(Events!$A:$A,MATCH(I13,Events!$J:$J,0)),"") | K16: =IFERROR(INDEX(Events!$A:$A,MATCH(K13,Events!$J:$J,0)),"") | M16: Daily Load report | O16: =IFERROR(INDEX(Events!$A:$A,MATCH(O13,Events!$J:$J,0)),"")
C17: =IF(O13="","",IF(MONTH(O13+1)<>MONTH(O13),"",O13+1)) -> 45669 | D17: =IFERROR(INDEX(Events!$A:$A,MATCH(C17,Events!$G:$G,0)),"") | E17: =IF(C17="","",IF(MONTH(C17+1)<>MONTH(C17),"",C17+1)) -> 45670 | F17: W8 | G17: =IF(E17="","",IF(MONTH(E17+1)<>MONTH(E17),"",E17+1)) -> 45671 | H17: W9 | I17: =IF(G17="","",IF(MONTH(G17+1)<>MONTH(G17),"",G17+1)) -> 45672 | J17: W10 | K17: =IF(I17="","",IF(MONTH(I17+1)<>MONTH(I17),"",I17+1)) -> 45673 | L17: W11 | M17: =IF(K17="","",IF(MONTH(K17+1)<>MONTH(K17),"",K17+1)) -> 45674 | N17: W12 | O17: =IF(M17="","",IF(MONTH(M17+1)<>MONTH(M17),"",M17+1)) -> 45675 | P17: =IFERROR(INDEX(Events!$A:$A,MATCH(O17,Events!$G:$G,0)),"") | R17: week 3
C18: =IFERROR(INDEX(Events!$A:$A,MATCH(C17,Events!$H:$H,0)),"") | D18: =IFERROR(INDEX(Events!#REF!,MATCH(C18,Events!A:A,0)),"") | E18: =IFERROR(INDEX(Events!$A:$A,MATCH(E17,Events!$H:$H,0)),"") | F18: =IFERROR(INDEX(Events!#REF!,MATCH(E18,Events!C:C,0)),"") | G18: =IFERROR(INDEX(Events!$A:$A,MATCH(G17,Events!$H:$H,0)),"") | H18: =IFERROR(INDEX(Events!#REF!,MATCH(G18,Events!E:E,0)),"") | I18: =IFERROR(INDEX(Events!$A:$A,MATCH(I17,Events!$H:$H,0)),"") | J18: =IFERROR(INDEX(Events!A:A,MATCH(I18,Events!G:G,0)),"") | K18: =IFERROR(INDEX(Events!$A:$A,MATCH(K17,Events!$H:$H,0)),"") | L18: =IFERROR(INDEX(Events!C:C,MATCH(K18,Events!I:I,0)),"") | M18: =IFERROR(INDEX(Events!$A:$A,MATCH(M17,Events!$H:$H,0)),"") | N18: =IFERROR(INDEX(Events!E:E,MATCH(M18,Events!#REF!,0)),"") | O18: =IFERROR(INDEX(Events!$A:$A,MATCH(O17,Events!$H:$H,0)),"") | P18: =IFERROR(INDEX(Events!G:G,MATCH(O18,Events!K:K,0)),"")
C19: =IFERROR(INDEX(Events!$A:$A,MATCH(C17,Events!$I:$I,0)),"") | E19: EPM Dashboard | G19: =IFERROR(INDEX(Events!$A:$A,MATCH(G17,Events!$I:$I,0)),"") | I19: =IFERROR(INDEX(Events!$A:$A,MATCH(I17,Events!$I:$I,0)),"") | K19: =IFERROR(INDEX(Events!$A:$A,MATCH(K17,Events!$I:$I,0)),"") | M19: =IFERROR(INDEX(Events!$A:$A,MATCH(M17,Events!$I:$I,0)),"") | O19: =IFERROR(INDEX(Events!$A:$A,MATCH(O17,Events!$I:$I,0)),"")
C20: =IFERROR(INDEX(Events!$A:$A,MATCH(C17,Events!$J:$J,0)),"") | E20: Daily Load report | G20: Daily Load report | I20: Daily Load report | K20: Daily Load report | M20: Daily Load report | O20: =IFERROR(INDEX(Events!$A:$A,MATCH(O17,Events!$J:$J,0)),"")
C21: =IF(O17="","",IF(MONTH(O17+1)<>MONTH(O17),"",O17+1)) -> 45676 | D21: =IFERROR(INDEX(Events!$A:$A,MATCH(C21,Events!$G:$G,0)),"") | E21: =IF(C21="","",IF(MONTH(C21+1)<>MONTH(C21),"",C21+1)) -> 45677 | F21: =IFERROR(INDEX(Events!$A:$A,MATCH(E21,Events!$G:$G,0)),"") -> ML King Day | G21: =IF(E21="","",IF(MONTH(E21+1)<>MONTH(E21),"",E21+1)) -> 45678 | H21: =IFERROR(INDEX(Events!$A:$A,MATCH(G21,Events!$G:$G,0)),"") | I21: =IF(G21="","",IF(MONTH(G21+1)<>MONTH(G21),"",G21+1)) -> 45679 | J21: =IFERROR(INDEX(Events!$A:$A,MATCH(I21,Events!$G:$G,0)),"") | K21: =IF(I21="","",IF(MONTH(I21+1)<>MONTH(I21),"",I21+1)) -> 45680 | L21: =IFERROR(INDEX(Events!$A:$A,MATCH(K21,Events!$G:$G,0)),"") | M21: =IF(K21="","",IF(MONTH(K21+1)<>MONTH(K21),"",K21+1)) -> 45681 | N21: =IFERROR(INDEX(Events!$A:$A,MATCH(M21,Events!$G:$G,0)),"") | O21: =IF(M21="","",IF(MONTH(M21+1)<>MONTH(M21),"",M21+1)) -> 45682 | P21: =IFERROR(INDEX(Events!$A:$A,MATCH(O21,Events!$G:$G,0)),"") | R21: week 4
C22: =IFERROR(INDEX(Events!$A:$A,MATCH(C21,Events!$H:$H,0)),"") | D22: =IFERROR(INDEX(Events!#REF!,MATCH(C22,Events!A:A,0)),"") | E22: =IFERROR(INDEX(Events!$A:$A,MATCH(E21,Events!$H:$H,0)),"") | F22: =IFERROR(INDEX(Events!#REF!,MATCH(E22,Events!C:C,0)),"") | G22: =IFERROR(INDEX(Events!$A:$A,MATCH(G21,Events!$H:$H,0)),"") | H22: =IFERROR(INDEX(Events!#REF!,MATCH(G22,Events!E:E,0)),"") | I22: =IFERROR(INDEX(Events!$A:$A,MATCH(I21,Events!$H:$H,0)),"") | J22: =IFERROR(INDEX(Events!A:A,MATCH(I22,Events!G:G,0)),"") | K22: =IFERROR(INDEX(Events!$A:$A,MATCH(K21,Events!$H:$H,0)),"") | L22: =IFERROR(INDEX(Events!C:C,MATCH(K22,Events!I:I,0)),"") | M22: =IFERROR(INDEX(Events!$A:$A,MATCH(M21,Events!$H:$H,0)),"") | N22: =IFERROR(INDEX(Events!E:E,MATCH(M22,Events!#REF!,0)),"") | O22: =IFERROR(INDEX(Events!$A:$A,MATCH(O21,Events!$H:$H,0)),"") | P22: =IFERROR(INDEX(Events!G:G,MATCH(O22,Events!K:K,0)),"")
C23: =IFERROR(INDEX(Events!$A:$A,MATCH(C21,Events!$I:$I,0)),"") | E23: EPM Dashboard | G23: =IFERROR(INDEX(Events!$A:$A,MATCH(G21,Events!$I:$I,0)),"") | I23: =IFERROR(INDEX(Events!$A:$A,MATCH(I21,Events!$I:$I,0)),"") | K23: =IFERROR(INDEX(Events!$A:$A,MATCH(K21,Events!$I:$I,0)),"") | M23: =IFERROR(INDEX(Events!$A:$A,MATCH(M21,Events!$I:$I,0)),"") | O23: =IFERROR(INDEX(Events!$A:$A,MATCH(O21,Events!$I:$I,0)),"")
C24: =IFERROR(INDEX(Events!$A:$A,MATCH(C21,Events!$J:$J,0)),"") | E24: Daily Load report | G24: Daily Load report | I24: Daily Load report | K24: Daily Load report | M24: Daily Load report | O24: =IFERROR(INDEX(Events!$A:$A,MATCH(O21,Events!$J:$J,0)),"")
C25: =IF(O21="","",IF(MONTH(O21+1)<>MONTH(O21),"",O21+1)) -> 45683 | D25: =IFERROR(INDEX(Events!$A:$A,MATCH(C25,Events!$G:$G,0)),"") | E25: =IF(C25="","",IF(MONTH(C25+1)<>MONTH(C25),"",C25+1)) -> 45684 | F25: =IFERROR(INDEX(Events!$A:$A,MATCH(E25,Events!$G:$G,0)),"") | G25: =IF(E25="","",IF(MONTH(E25+1)<>MONTH(E25),"",E25+1)) -> 45685 | H25: =IFERROR(INDEX(Events!$A:$A,MATCH(G25,Events!$G:$G,0)),"") | I25: =IF(G25="","",IF(MONTH(G25+1)<>MONTH(G25),"",G25+1)) -> 45686 | J25: =IFERROR(INDEX(Events!$A:$A,MATCH(I25,Events!$G:$G,0)),"") -> Chinese New Year | K25: =IF(I25="","",IF(MONTH(I25+1)<>MONTH(I25),"",I25+1)) -> 45687 | L25: DTG2 | M25: =IF(K25="","",IF(MONTH(K25+1)<>MONTH(K25),"",K25+1)) -> 45688 | N25: DTG1 | O25: =IF(M25="","",IF(MONTH(M25+1)<>MONTH(M25),"",M25+1)) | P25: =IFERROR(INDEX(Events!$A:$A,MATCH(O25,Events!$G:$G,0)),"") | R25: week 5
C26: =IFERROR(INDEX(Events!$A:$A,MATCH(C25,Events!$H:$H,0)),"") | D26: =IFERROR(INDEX(Events!#REF!,MATCH(C26,Events!A:A,0)),"") | E26: =IFERROR(INDEX(Events!$A:$A,MATCH(E25,Events!$H:$H,0)),"") | F26: =IFERROR(INDEX(Events!#REF!,MATCH(E26,Events!C:C,0)),"") | G26: =IFERROR(INDEX(Events!$A:$A,MATCH(G25,Events!$H:$H,0)),"") | H26: =IFERROR(INDEX(Events!#REF!,MATCH(G26,Events!E:E,0)),"") | I26: PRELIM EARNINGS | J26: =IFERROR(INDEX(Events!A:A,MATCH(I26,Events!G:G,0)),"") | K26: =IFERROR(INDEX(Events!$A:$A,MATCH(K25,Events!$H:$H,0)),"") | L26: =IFERROR(INDEX(Events!C:C,MATCH(K26,Events!I:I,0)),"") | M26: =IFERROR(INDEX(Events!$A:$A,MATCH(M25,Events!$H:$H,0)),"") | N26: =IFERROR(INDEX(Events!E:E,MATCH(M26,Events!#REF!,0)),"") | O26: =IFERROR(INDEX(Events!$A:$A,MATCH(O25,Events!$H:$H,0)),"") | P26: =IFERROR(INDEX(Events!G:G,MATCH(O26,Events!K:K,0)),"")
C27: =IFERROR(INDEX(Events!$A:$A,MATCH(C25,Events!$I:$I,0)),"") | E27: EPM Dashboard | G27: =IFERROR(INDEX(Events!$A:$A,MATCH(G25,Events!$I:$I,0)),"") | I27: =IFERROR(INDEX(Events!$A:$A,MATCH(I25,Events!$I:$I,0)),"") | K27: EPM Dashboard | M27: EPM Dashboard | O27: =IFERROR(INDEX(Events!$A:$A,MATCH(O25,Events!$I:$I,0)),"")
C28: =IFERROR(INDEX(Events!$A:$A,MATCH(C25,Events!$J:$J,0)),"") | E28: Daily Load report | G28: Daily Load report | I28: Daily Load report | K28: Daily Load report | M28: Daily Load report | O28: =IFERROR(INDEX(Events!$A:$A,MATCH(O25,Events!$J:$J,0)),"")
C29: =IF(O25="","",IF(MONTH(O25+1)<>MONTH(O25),"",O25+1)) | D29: =IFERROR(INDEX(Events!$A:$A,MATCH(C29,Events!$G:$G,0)),"") | E29: =IF(C29="","",IF(MONTH(C29+1)<>MONTH(C29),"",C29+1)) | F29: =IFERROR(INDEX(Events!$A:$A,MATCH(E29,Events!$G:$G,0)),"")
C30: =IFERROR(INDEX(Events!$A:$A,MATCH(C29,Events!$H:$H,0)),"") | D30: =IFERROR(INDEX(Events!#REF!,MATCH(C30,Events!A:A,0)),"") | E30: =IFERROR(INDEX(Events!$A:$A,MATCH(E29,Events!$H:$H,0)),"") | F30: =IFERROR(INDEX(Events!#REF!,MATCH(E30,Events!C:C,0)),"")
C31: =IFERROR(INDEX(Events!$A:$A,MATCH(C29,Events!$I:$I,0)),"") | E31: =IFERROR(INDEX(Events!$A:$A,MATCH(E29,Events!$I:$I,0)),"")
C32: =IFERROR(INDEX(Events!$A:$A,MATCH(C29,Events!$J:$J,0)),"")
C34: Date: | D34: =DATE(YEAR('Q1'!$D$7),MONTH('Q1'!$D$7)+1,1) -> 45689
A35: =D34 -> 45689 | C35: Sunday | E35: Monday | G35: Tuesday | I35: Wednesday | K35: Thursday | M35: Friday | O35: Saturday | R35: week
C36: =IF(WEEKDAY($D$34,1)=startday,$D$34,"") | D36: =IFERROR(INDEX(Events!$A:$A,MATCH(C36,Events!$G:$G,0)),"") | E36: =IF(C36="",IF(WEEKDAY($D$34,1)=MOD(startday,7)+1,$D$34,""),C36+1) | F36: =IFERROR(INDEX(Events!$A:$A,MATCH(E36,Events!$G:$G,0)),"") | G36: =IF(E36="",IF(WEEKDAY($D$34,1)=MOD(startday+1,7)+1,$D$34,""),E36+1) | H36: =IFERROR(INDEX(Events!$A:$A,MATCH(G36,Events!$G:$G,0)),"") | I36: =IF(G36="",IF(WEEKDAY($D$34,1)=MOD(startday+2,7)+1,$D$34,""),G36+1) | J36: =IFERROR(INDEX(Events!$A:$A,MATCH(I36,Events!$G:$G,0)),"") | K36: =IF(I36="",IF(WEEKDAY($D$34,1)=MOD(startday+3,7)+1,$D$34,""),I36+1) | L36: =IFERROR(INDEX(Events!$A:$A,MATCH(K36,Events!$G:$G,0)),"") | M36: =IF(K36="",IF(WEEKDAY($D$34,1)=MOD(startday+4,7)+1,$D$34,""),K36+1) | N36: =IFERROR(INDEX(Events!$A:$A,MATCH(M36,Events!$G:$G,0)),"") | O36: =IF(M36="",IF(WEEKDAY($D$34,1)=MOD(startday+5,7)+1,$D$34,""),M36+1) -> 45689 | P36: =IFERROR(INDEX(Events!$A:$A,MATCH(O36,Events!$G:$G,0)),"") | R36: week 5 (cont)
C37: =IFERROR(INDEX(Events!$A:$A,MATCH(C36,Events!$H:$H,0)),"") | E37: =IFERROR(INDEX(Events!$A:$A,MATCH(E36,Events!$H:$H,0)),"") | G37: =IFERROR(INDEX(Events!$A:$A,MATCH(G36,Events!$H:$H,0)),"") | I37: =IFERROR(INDEX(Events!$A:$A,MATCH(I36,Events!$H:$H,0)),"") | K37: =IFERROR(INDEX(Events!$A:$A,MATCH(K36,Events!$H:$H,0)),"") | M37: =IFERROR(INDEX(Events!$A:$A,MATCH(M36,Events!$H:$H,0)),"") | O37: =IFERROR(INDEX(Events!$A:$A,MATCH(O36,Events!$H:$H,0)),"")
C38: =IFERROR(INDEX(Events!$A:$A,MATCH(C36,Events!$I:$I,0)),"") | E38: =IFERROR(INDEX(Events!$A:$A,MATCH(E36,Events!$I:$I,0)),"") | G38: =IFERROR(INDEX(Events!$A:$A,MATCH(G36,Events!$I:$I,0)),"") | I38: =IFERROR(INDEX(Events!$A:$A,MATCH(I36,Events!$I:$I,0)),"") | K38: =IFERROR(INDEX(Events!$A:$A,MATCH(K36,Events!$I:$I,0)),"") | M38: =IFERROR(INDEX(Events!$A:$A,MATCH(M36,Events!$I:$I,0)),"") | O38: =IFERROR(INDEX(Events!$A:$A,MATCH(O36,Events!$I:$I,0)),"")
C39: =IFERROR(INDEX(Events!$A:$A,MATCH(C36,Events!$J:$J,0)),"") | E39: =IFERROR(INDEX(Events!$A:$A,MATCH(E36,Events!$J:$J,0)),"") | G39: =IFERROR(INDEX(Events!$A:$A,MATCH(G36,Events!$J:$J,0)),"") | I39: =IFERROR(INDEX(Events!$A:$A,MATCH(I36,Events!$J:$J,0)),"") | K39: =IFERROR(INDEX(Events!$A:$A,MATCH(K36,Events!$J:$J,0)),"") | M39: =IFERROR(INDEX(Events!$A:$A,MATCH(M36,Events!$J:$J,0)),"") | O39: Daily Load report
C40: =IF(O36="","",IF(MONTH(O36+1)<>MONTH(O36),"",O36+1)) -> 45690 | D40: =IFERROR(INDEX(Events!$A:$A,MATCH(C40,Events!$G:$G,0)),"") -> Groundhog Day | E40: =IF(C40="","",IF(MONTH(C40+1)<>MONTH(C40),"",C40+1)) -> 45691 | F40: W1 | G40: =IF(E40="","",IF(MONTH(E40+1)<>MONTH(E40),"",E40+1)) -> 45692 | H40: W2 | I40: =IF(G40="","",IF(MONTH(G40+1)<>MONTH(G40),"",G40+1)) -> 45693 | J40: W3 | K40: =IF(I40="","",IF(MONTH(I40+1)<>MONTH(I40),"",I40+1)) -> 45694 | L40: W4 | M40: =IF(K40="","",IF(MONTH(K40+1)<>MONTH(K40),"",K40+1)) -> 45695 | N40: W5 | O40: =IF(M40="","",IF(MONTH(M40+1)<>MONTH(M40),"",M40+1)) -> 45696 | P40: =IFERROR(INDEX(Events!$A:$A,MATCH(O40,Events!$G:$G,0)),"") | R40: week 6
C41: =IFERROR(INDEX(Events!$A:$A,MATCH(C40,Events!$H:$H,0)),"") | E41: January Final | G41: Roll to next mth | H41: =IFERROR(INDEX(Events!#REF!,MATCH(G41,Events!E:E,0)),"") | I41: =IFERROR(INDEX(Events!$A:$A,MATCH(I40,Events!$H:$H,0)),"") | K41: =IFERROR(INDEX(Events!$A:$A,MATCH(K40,Events!$H:$H,0)),"") | M41: GTN update | N41: =IFERROR(INDEX(Events!E:E,MATCH(M41,Events!#REF!,0)),"") | O41: =IFERROR(INDEX(Events!$A:$A,MATCH(O40,Events!$H:$H,0)),"")
C42: =IFERROR(INDEX(Events!$A:$A,MATCH(C40,Events!$I:$I,0)),"") | E42: EPM Dashboard | G42: =IFERROR(INDEX(Events!$A:$A,MATCH(G40,Events!$I:$I,0)),"") | I42: =IFERROR(INDEX(Events!$A:$A,MATCH(I40,Events!$I:$I,0)),"") | K42: =IFERROR(INDEX(Events!$A:$A,MATCH(K40,Events!$I:$I,0)),"") | M42: =IFERROR(INDEX(Events!$A:$A,MATCH(M40,Events!$I:$I,0)),"") | O42: =IFERROR(INDEX(Events!$A:$A,MATCH(O40,Events!$I:$I,0)),"")
C43: =IFERROR(INDEX(Events!$A:$A,MATCH(C40,Events!$J:$J,0)),"") | E43: Daily Load report | G43: Daily Load report | I43: Daily Load report | K43: Daily Load report | M43: Daily Load report | O43: =IFERROR(INDEX(Events!$A:$A,MATCH(O40,Events!$J:$J,0)),"")
...

Sheet Q3
C5: Load Calendar | I5: =D7 -> 45839
C7: Date: | D7: =DATE(YEAR('Q1'!$D$7),MONTH('Q1'!$D$7)+6,1) -> 45839
A8: =D7 -> 45839 | C8: Sunday | E8: Monday | G8: Tuesday | I8: Wednesday | K8: Thursday | M8: Friday | O8: Saturday | R8: week
C9: =IF(WEEKDAY($D$7,1)=startday,$D$7,"") | D9: =IFERROR(INDEX(Events!$A:$A,MATCH(C9,Events!$G:$G,0)),"") | E9: =IF(C9="",IF(WEEKDAY($D$7,1)=MOD(startday,7)+1,$D$7,""),C9+1) | F9: =IFERROR(INDEX(Events!$A:$A,MATCH(E9,Events!$G:$G,0)),"") | G9: =IF(E9="",IF(WEEKDAY($D$7,1)=MOD(startday+1,7)+1,$D$7,""),E9+1) -> 45839 | H9: W1 | I9: =IF(G9="",IF(WEEKDAY($D$7,1)=MOD(startday+2,7)+1,$D$7,""),G9+1) -> 45840 | J9: W2 | K9: =IF(I9="",IF(WEEKDAY($D$7,1)=MOD(startday+3,7)+1,$D$7,""),I9+1) -> 45841 | L9: W3 | M9: =IF(K9="",IF(WEEKDAY($D$7,1)=MOD(startday+4,7)+1,$D$7,""),K9+1) -> 45842 | N9: Intependence Day | O9: =IF(M9="",IF(WEEKDAY($D$7,1)=MOD(startday+5,7)+1,$D$7,""),M9+1) -> 45843 | P9: =IFERROR(INDEX(Events!$A:$A,MATCH(O9,Events!$G:$G,0)),"") | R9: week 1
G10: Final Load | H10: =IFERROR(INDEX(Events!#REF!,MATCH(G10,Events!E:E,0)),"") | I10: WW courtesy run | K10: No WW Load Run | M10: No WW Load Run | O10: =IFERROR(INDEX(Events!$A:$A,MATCH(O8,Events!$H:$H,0)),"") | P10: =IFERROR(INDEX(Events!G:G,MATCH(O10,Events!K:K,0)),"")
C11: =IFERROR(INDEX(Events!$A:$A,MATCH(C9,Events!$H:$H,0)),"") | D11: =IFERROR(INDEX(Events!#REF!,MATCH(C11,Events!A:A,0)),"") | E11: =IFERROR(INDEX(Events!$A:$A,MATCH(E9,Events!$H:$H,0)),"") | F11: =IFERROR(INDEX(Events!#REF!,MATCH(E11,Events!C:C,0)),"") | G11: WW Load Run | I11: =IFERROR(INDEX(Events!$A:$A,MATCH(I9,Events!$H:$H,0)),"") | J11: =IFERROR(INDEX(Events!A:A,MATCH(I11,Events!G:G,0)),"") | K11: =IFERROR(INDEX(Events!$A:$A,MATCH(K9,Events!$H:$H,0)),"") | L11: =IFERROR(INDEX(Events!C:C,MATCH(K11,Events!I:I,0)),"") | M11: =IFERROR(INDEX(Events!$A:$A,MATCH(M9,Events!$H:$H,0)),"") | N11: =IFERROR(INDEX(Events!E:E,MATCH(M11,Events!#REF!,0)),"") | O11: =IFERROR(INDEX(Events!$A:$A,MATCH(O9,Events!$H:$H,0)),"") | P11: =IFERROR(INDEX(Events!G:G,MATCH(O11,Events!K:K,0)),"")
C12: =IFERROR(INDEX(Events!$A:$A,MATCH(C9,Events!$I:$I,0)),"") | E12: =IFERROR(INDEX(Events!$A:$A,MATCH(E9,Events!$I:$I,0)),"") | I12: =IFERROR(INDEX(Events!$A:$A,MATCH(I9,Events!$I:$I,0)),"") | K12: =IFERROR(INDEX(Events!$A:$A,MATCH(K9,Events!$I:$I,0)),"") | M12: =IFERROR(INDEX(Events!$A:$A,MATCH(M9,Events!$I:$I,0)),"") | O12: =IFERROR(INDEX(Events!$A:$A,MATCH(O9,Events!$I:$I,0)),"")
C13: =IFERROR(INDEX(Events!$A:$A,MATCH(C9,Events!$J:$J,0)),"") | E13: =IFERROR(INDEX(Events!$A:$A,MATCH(E9,Events!$J:$J,0)),"") | G13: Blackout | I13: =IFERROR(INDEX(Events!$A:$A,MATCH(I9,Events!$J:$J,0)),"") | K13: =IFERROR(INDEX(Events!$A:$A,MATCH(K9,Events!$J:$J,0)),"") | M13: =IFERROR(INDEX(Events!$A:$A,MATCH(M9,Events!$J:$J,0)),"") | O13: =IFERROR(INDEX(Events!$A:$A,MATCH(O9,Events!$J:$J,0)),"")
C14: =IF(O9="","",IF(MONTH(O9+1)<>MONTH(O9),"",O9+1)) -> 45844 | D14: =IFERROR(INDEX(Events!$A:$A,MATCH(C14,Events!$G:$G,0)),"") | E14: =IF(C14="","",IF(MONTH(C14+1)<>MONTH(C14),"",C14+1)) -> 45845 | F14: W4 | G14: =IF(E14="","",IF(MONTH(E14+1)<>MONTH(E14),"",E14+1)) -> 45846 | H14: W5 | I14: =IF(G14="","",IF(MONTH(G14+1)<>MONTH(G14),"",G14+1)) -> 45847 | J14: W6 | K14: =IF(I14="","",IF(MONTH(I14+1)<>MONTH(I14),"",I14+1)) -> 45848 | L14: W7 | M14: =IF(K14="","",IF(MONTH(K14+1)<>MONTH(K14),"",K14+1)) -> 45849 | N14: W8 | O14: =IF(M14="","",IF(MONTH(M14+1)<>MONTH(M14),"",M14+1)) -> 45850 | P14: =IFERROR(INDEX(Events!$A:$A,MATCH(O14,Events!$G:$G,0)),"") | R14: week 2
C15: No WW Load Run | E15: No WW Load Run | G15: No WW Load Run | I15: WW Load Run | K15: WW Load Run | M15: WW Load Run | O15: =IFERROR(INDEX(Events!$A:$A,MATCH(O14,Events!$H:$H,0)),"")
C16: =IFERROR(INDEX(Events!$A:$A,MATCH(C14,Events!$I:$I,0)),"") | E16: =IFERROR(INDEX(Events!$A:$A,MATCH(E14,Events!$I:$I,0)),"") | G16: =IFERROR(INDEX(Events!$A:$A,MATCH(G14,Events!$H:$H,0)),"") | H16: =IFERROR(INDEX(Events!#REF!,MATCH(G16,Events!E:E,0)),"") | I16: Roll to next qtr | J16: =IFERROR(INDEX(Events!#REF!,MATCH(I16,Events!G:G,0)),"") | K16: EPM Dashboard | M16: EPM Dashboard | O16: =IFERROR(INDEX(Events!$A:$A,MATCH(O14,Events!$H:$H,0)),"") | P16: =IFERROR(INDEX(Events!G:G,MATCH(O16,Events!K:K,0)),"")
C17: =IFERROR(INDEX(Events!$A:$A,MATCH(C15,Events!$I:$I,0)),"") | E17: =IFERROR(INDEX(Events!$A:$A,MATCH(E15,Events!$I:$I,0)),"") | G17: =IFERROR(INDEX(Events!$A:$A,MATCH(G15,Events!$I:$I,0)),"") | I17: AUR valuation | K17: Daily Load report | M17: Daily Load report | O17: =IFERROR(INDEX(Events!$A:$A,MATCH(O14,Events!$I:$I,0)),"")
C18: =IFERROR(INDEX(Events!$A:$A,MATCH(C14,Events!$J:$J,0)),"") | E18: =IFERROR(INDEX(Events!$A:$A,MATCH(E14,Events!$J:$J,0)),"") | G18: =IFERROR(INDEX(Events!$A:$A,MATCH(G14,Events!$J:$J,0)),"") | I18: =IFERROR(INDEX(Events!$A:$A,MATCH(I14,Events!$J:$J,0)),"") | K18: =IFERROR(INDEX(Events!$A:$A,MATCH(K14,Events!$J:$J,0)),"") | M18: GTN update | N18: =IFERROR(INDEX([1]Events!E:E,MATCH(M18,[1]Events!#REF!,0)),"") | O18: =IFERROR(INDEX(Events!$A:$A,MATCH(O14,Events!$J:$J,0)),"")
C19: =IF(O14="","",IF(MONTH(O14+1)<>MONTH(O14),"",O14+1)) -> 45851 | D19: =IFERROR(INDEX(Events!$A:$A,MATCH(C19,Events!$G:$G,0)),"") | E19: =IF(C19="","",IF(MONTH(C19+1)<>MONTH(C19),"",C19+1)) -> 45852 | F19: =IFERROR(INDEX(Events!$A:$A,MATCH(E19,Events!$G:$G,0)),"") | G19: =IF(E19="","",IF(MONTH(E19+1)<>MONTH(E19),"",E19+1)) -> 45853 | H19: =IFERROR(INDEX(Events!$A:$A,MATCH(G19,Events!$G:$G,0)),"") | I19: =IF(G19="","",IF(MONTH(G19+1)<>MONTH(G19),"",G19+1)) -> 45854 | J19: =IFERROR(INDEX(Events!$A:$A,MATCH(I19,Events!$G:$G,0)),"") | K19: =IF(I19="","",IF(MONTH(I19+1)<>MONTH(I19),"",I19+1)) -> 45855 | L19: =IFERROR(INDEX(Events!$A:$A,MATCH(K19,Events!$G:$G,0)),"") | M19: =IF(K19="","",IF(MONTH(K19+1)<>MONTH(K19),"",K19+1)) -> 45856 | N19: =IFERROR(INDEX(Events!$A:$A,MATCH(M19,Events!$G:$G,0)),"") | O19: =IF(M19="","",IF(MONTH(M19+1)<>MONTH(M19),"",M19+1)) -> 45857 | P19: =IFERROR(INDEX(Events!$A:$A,MATCH(O19,Events!$G:$G,0)),"") | R19: week 3
E20: WW Load Run | G20: WW Load Run | I20: WW Load Run | K20: WW Load Run | M20: WW Load Run | O20: =IFERROR(INDEX(Events!$A:$A,MATCH(O19,Events!$H:$H,0)),"")
E21: EPM Dashboard | G21: EPM Dashboard | I21: EPM Dashboard | K21: EPM Dashboard | M21: EPM Dashboard | O21: =IFERROR(INDEX(Events!$A:$A,MATCH(O19,Events!$H:$H,0)),"") | P21: =IFERROR(INDEX(Events!G:G,MATCH(O21,Events!K:K,0)),"")
E22: Daily Load report | G22: Daily Load report | I22: Daily Load report | K22: Daily Load report | M22: Daily Load report | O22: =IFERROR(INDEX(Events!$A:$A,MATCH(O19,Events!$I:$I,0)),"")
C23: =IFERROR(INDEX(Events!$A:$A,MATCH(C19,Events!$J:$J,0)),"") | E23: =IFERROR(INDEX(Events!$A:$A,MATCH(E19,Events!$J:$J,0)),"") | G23: =IFERROR(INDEX(Events!$A:$A,MATCH(G19,Events!$J:$J,0)),"") | I23: =IFERROR(INDEX(Events!$A:$A,MATCH(I19,Events!$J:$J,0)),"") | K23: =IFERROR(INDEX(Events!$A:$A,MATCH(K19,Events!$J:$J,0)),"") | M23: =IFERROR(INDEX(Events!$A:$A,MATCH(M19,Events!$J:$J,0)),"") | O23: =IFERROR(INDEX(Events!$A:$A,MATCH(O19,Events!$J:$J,0)),"")
C24: =IF(O19="","",IF(MONTH(O19+1)<>MONTH(O19),"",O19+1)) -> 45858 | D24: =IFERROR(INDEX(Events!$A:$A,MATCH(C24,Events!$G:$G,0)),"") | E24: =IF(C24="","",IF(MONTH(C24+1)<>MONTH(C24),"",C24+1)) -> 45859 | F24: =IFERROR(INDEX(Events!$A:$A,MATCH(E24,Events!$G:$G,0)),"") | G24: =IF(E24="","",IF(MONTH(E24+1)<>MONTH(E24),"",E24+1)) -> 45860 | H24: =IFERROR(INDEX(Events!$A:$A,MATCH(G24,Events!$G:$G,0)),"") | I24: =IF(G24="","",IF(MONTH(G24+1)<>MONTH(G24),"",G24+1)) -> 45861 | J24: =IFERROR(INDEX(Events!$A:$A,MATCH(I24,Events!$G:$G,0)),"") | K24: =IF(I24="","",IF(MONTH(I24+1)<>MONTH(I24),"",I24+1)) -> 45862 | L24: =IFERROR(INDEX(Events!$A:$A,MATCH(K24,Events!$G:$G,0)),"") | M24: =IF(K24="","",IF(MONTH(K24+1)<>MONTH(K24),"",K24+1)) -> 45863 | N24: =IFERROR(INDEX(Events!$A:$A,MATCH(M24,Events!$G:$G,0)),"") | O24: =IF(M24="","",IF(MONTH(M24+1)<>MONTH(M24),"",M24+1)) -> 45864 | P24: =IFERROR(INDEX(Events!$A:$A,MATCH(O24,Events!$G:$G,0)),"") | R24: week 4
E25: WW Load Run | G25: WW Load Run | I25: WW Load Run | K25: WW Load Run | M25: WW Load Run | O25: =IFERROR(INDEX(Events!$A:$A,MATCH(O24,Events!$H:$H,0)),"")
E26: EPM Dashboard | G26: EPM Dashboard | I26: EPM Dashboard | K26: EPM Dashboard | M26: EPM Dashboard | O26: =IFERROR(INDEX(Events!$A:$A,MATCH(O24,Events!$H:$H,0)),"") | P26: =IFERROR(INDEX(Events!G:G,MATCH(O26,Events!K:K,0)),"")
E27: Daily Load report | G27: Daily Load report | I27: Daily Load report | K27: Daily Load report | M27: Daily Load report | O27: =IFERROR(INDEX(Events!$A:$A,MATCH(O24,Events!$I:$I,0)),"")
C28: =IFERROR(INDEX(Events!$A:$A,MATCH(C24,Events!$J:$J,0)),"") | E28: =IFERROR(INDEX(Events!$A:$A,MATCH(E24,Events!$J:$J,0)),"") | G28: =IFERROR(INDEX(Events!$A:$A,MATCH(G24,Events!$J:$J,0)),"") | I28: =IFERROR(INDEX(Events!$A:$A,MATCH(I24,Events!$J:$J,0)),"") | K28: =IFERROR(INDEX(Events!$A:$A,MATCH(K24,Events!$J:$J,0)),"") | M28: =IFERROR(INDEX(Events!$A:$A,MATCH(M24,Events!$J:$J,0)),"") | O28: =IFERROR(INDEX(Events!$A:$A,MATCH(O24,Events!$J:$J,0)),"")
C29: =IF(O24="","",IF(MONTH(O24+1)<>MONTH(O24),"",O24+1)) -> 45865 | E29: =IF(C29="","",IF(MONTH(C29+1)<>MONTH(C29),"",C29+1)) -> 45866 | F29: =IFERROR(INDEX(Events!$A:$A,MATCH(E29,Events!$G:$G,0)),"") | G29: =IF(E29="","",IF(MONTH(E29+1)<>MONTH(E29),"",E29+1)) -> 45867 | H29: =IFERROR(INDEX(Events!$A:$A,MATCH(G29,Events!$G:$G,0)),"") | I29: =IF(G29="","",IF(MONTH(G29+1)<>MONTH(G29),"",G29+1)) -> 45868 | J29: =IFERROR(INDEX(Events!$A:$A,MATCH(I29,Events!$G:$G,0)),"") | K29: =IF(I29="","",IF(MONTH(I29+1)<>MONTH(I29),"",I29+1)) -> 45869 | L29: =IFERROR(INDEX(Events!$A:$A,MATCH(K29,Events!$G:$G,0)),"") | M29: =IF(K29="","",IF(MONTH(K29+1)<>MONTH(K29),"",K29+1)) | N29: =IFERROR(INDEX(Events!$A:$A,MATCH(M29,Events!$G:$G,0)),"") | O29: =IF(M29="","",IF(MONTH(M29+1)<>MONTH(M29),"",M29+1)) | P29: =IFERROR(INDEX(Events!$A:$A,MATCH(O29,Events!$G:$G,0)),"") | R29: week 5
E30: WW Load Run | G30: WW Load Run | I30: WW Load Run | K30: WW Load Run
E31: EPM Dashboard | G31: EPM Dashboard | I31: EPM Dashboard | K31: EPM Dashboard | O31: =IFERROR(INDEX(Events!$A:$A,MATCH(O29,Events!$H:$H,0)),"") | P31: =IFERROR(INDEX(Events!G:G,MATCH(O31,Events!K:K,0)),"")
E32: Daily Load report | G32: Daily Load report | I32: Daily Load report | K32: Daily Load report | O32: =IFERROR(INDEX(Events!$A:$A,MATCH(O29,Events!$I:$I,0)),"")
C33: =IFERROR(INDEX(Events!$A:$A,MATCH(C29,Events!$J:$J,0)),"") | E33: =IFERROR(INDEX(Events!$A:$A,MATCH(E29,Events!$J:$J,0)),"") | G33: =IFERROR(INDEX(Events!$A:$A,MATCH(G29,Events!$J:$J,0)),"") | I33: =IFERROR(INDEX(Events!$A:$A,MATCH(I29,Events!$J:$J,0)),"") | K33: =IFERROR(INDEX(Events!$A:$A,MATCH(K29,Events!$J:$J,0)),"") | M33: =IFERROR(INDEX(Events!$A:$A,MATCH(M29,Events!$J:$J,0)),"") | O33: =IFERROR(INDEX(Events!$A:$A,MATCH(O29,Events!$J:$J,0)),"")
C34: =IF(O29="","",IF(MONTH(O29+1)<>MONTH(O29),"",O29+1)) | D34: =IFERROR(INDEX(Events!$A:$A,MATCH(C34,Events!$G:$G,0)),"") | E34: =IF(C34="","",IF(MONTH(C34+1)<>MONTH(C34),"",C34+1)) | F34: =IFERROR(INDEX(Events!$A:$A,MATCH(E34,Events!$G:$G,0)),"")
C35: =IFERROR(INDEX(Events!$A:$A,MATCH(C34,Events!$H:$H,0)),"") | D35: =IFERROR(INDEX(Events!#REF!,MATCH(C35,Events!A:A,0)),"") | E35: =IFERROR(INDEX(Events!$A:$A,MATCH(E34,Events!$H:$H,0)),"") | F35: =IFERROR(INDEX(Events!#REF!,MATCH(E35,Events!C:C,0)),"")
C36: =IFERROR(INDEX(Events!$A:$A,MATCH(C34,Events!$I:$I,0)),"") | E36: =IFERROR(INDEX(Events!$A:$A,MATCH(E34,Events!$I:$I,0)),"") | I36: =D39 -> 45870
C37: =IFERROR(INDEX(Events!$A:$A,MATCH(C34,Events!$J:$J,0)),"") | E37: =IFERROR(INDEX(Events!$A:$A,MATCH(E34,Events!$J:$J,0)),"")
C39: Date: | D39: =DATE(YEAR('Q1'!$D$7),MONTH('Q1'!$D$7)+7,1) -> 45870
A40: =D39 -> 45870 | C40: Sunday | E40: Monday | G40: Tuesday | I40: Wednesday | K40: Thursday | M40: Friday | O40: Saturday | R40: week
C41: =IF(WEEKDAY($D$39,1)=startday,$D$39,"") | D41: =IFERROR(INDEX(Events!$A:$A,MATCH(C41,Events!$G:$G,0)),"") | E41: =IF(C41="",IF(WEEKDAY($D$39,1)=MOD(startday,7)+1,$D$39,""),C41+1) | F41: =IFERROR(INDEX(Events!$A:$A,MATCH(E41,Events!$G:$G,0)),"") | G41: =IF(E41="",IF(WEEKDAY($D$39,1)=MOD(startday+1,7)+1,$D$39,""),E41+1) | H41: =IFERROR(INDEX(Events!$A:$A,MATCH(G41,Events!$G:$G,0)),"") | I41: =IF(G41="",IF(WEEKDAY($D$39,1)=MOD(startday+2,7)+1,$D$39,""),G41+1) | J41: =IFERROR(INDEX(Events!$A:$A,MATCH(I41,Events!$G:$G,0)),"") | K41: =IF(I41="",IF(WEEKDAY($D$39,1)=MOD(startday+3,7)+1,$D$39,""),I41+1) | L41: =IFERROR(INDEX(Events!$A:$A,MATCH(K41,Events!$G:$G,0)),"") | M41: =IF(K41="",IF(WEEKDAY($D$39,1)=MOD(startday+4,7)+1,$D$39,""),K41+1) -> 45870 | N41: W1 | O41: =IF(M41="",IF(WEEKDAY($D$39,1)=MOD(startday+5,7)+1,$D$39,""),M41+1) -> 45871 | P41: =IFERROR(INDEX(Events!$A:$A,MATCH(O41,Events!$G:$G,0)),"") | R41: week 5 (cont)
M42: WW Load Run | O42: =IFERROR(INDEX(Events!$A:$A,MATCH(O41,Events!$H:$H,0)),"")
C43: =IFERROR(INDEX(Events!$A:$A,MATCH(C41,Events!$H:$H,0)),"") | E43: =IFERROR(INDEX(Events!$A:$A,MATCH(E41,Events!$H:$H,0)),"") | G43: =IFERROR(INDEX(Events!$A:$A,MATCH(G41,Events!$H:$H,0)),"") | I43: =IFERROR(INDEX(Events!$A:$A,MATCH(I41,Events!$H:$H,0)),"") | K43: =IFERROR(INDEX(Events!$A:$A,MATCH(K41,Events!$H:$H,0)),"") | M43: EPM Dashboard | O43: =IFERROR(INDEX(Events!$A:$A,MATCH(O41,Events!$H:$H,0)),"")
C44: =IFERROR(INDEX(Events!$A:$A,MATCH(C41,Events!$I:$I,0)),"") | E44: =IFERROR(INDEX(Events!$A:$A,MATCH(E41,Events!$I:$I,0)),"") | G44: =IFERROR(INDEX(Events!$A:$A,MATCH(G41,Events!$I:$I,0)),"") | I44: =IFERROR(INDEX(Events!$A:$A,MATCH(I41,Events!$I:$I,0)),"") | K44: =IFERROR(INDEX(Events!$A:$A,MATCH(K41,Events!$I:$I,0)),"") | M44: Daily Load report | O44: =IFERROR(INDEX(Events!$A:$A,MATCH(O41,Events!$I:$I,0)),"")
C45: =IFERROR(INDEX(Events!$A:$A,MATCH(C41,Events!$J:$J,0)),"") | E45: =IFERROR(INDEX(Events!$A:$A,MATCH(E41,Events!$J:$J,0)),"") | G45: =IFERROR(INDEX(Events!$A:$A,MATCH(G41,Events!$J:$J,0)),"") | I45: =IFERROR(INDEX(Events!$A:$A,MATCH(I41,Events!$J:$J,0)),"") | K45: =IFERROR(INDEX(Events!$A:$A,MATCH(K41,Events!$J:$J,0)),"") | M45: July Month End | O45: =IFERROR(INDEX(Events!$A:$A,MATCH(O41,Events!$J:$J,0)),"")
C46: =IF(O41="","",IF(MONTH(O41+1)<>MONTH(O41),"",O41+1)) -> 45872 | D46: =IFERROR(INDEX(Events!$A:$A,MATCH(C46,Events!$G:$G,0)),"") | E46: =IF(C46="","",IF(MONTH(C46+1)<>MONTH(C46),"",C46+1)) -> 45873 | F46: W2 | G46: =IF(E46="","",IF(MONTH(E46+1)<>MONTH(E46),"",E46+1)) -> 45874 | H46: W3 | I46: =IF(G46="","",IF(MONTH(G46+1)<>MONTH(G46),"",G46+1)) -> 45875 | J46: W4 | K46: =IF(I46="","",IF(MONTH(I46+1)<>MONTH(I46),"",I46+1)) -> 45876 | L46: W5 | M46: =IF(K46="","",IF(MONTH(K46+1)<>MONTH(K46),"",K46+1)) -> 45877 | N46: W6 | O46: =IF(M46="","",IF(MONTH(M46+1)<>MONTH(M46),"",M46+1)) -> 45878 | P46: =IFERROR(INDEX(Events!$A:$A,MATCH(O46,Events!$G:$G,0)),"") | R46: week 6
...

Sheet Q2
C5: Load Calendar
C7: Date: | D7: =DATE(YEAR('Q1'!$D$7),MONTH('Q1'!$D$7)+3,1) -> 45748
A8: =D7 -> 45748 | C8: Sunday | E8: Monday | G8: Tuesday | I8: Wednesday | K8: Thursday | M8: Friday | O8: Saturday | R8: week
C9: =IF(WEEKDAY($D$7,1)=startday,$D$7,"") | D9: =IFERROR(INDEX(Events!$A:$A,MATCH(C9,Events!$G:$G,0)),"") | E9: =IF(C9="",IF(WEEKDAY($D$7,1)=MOD(startday,7)+1,$D$7,""),C9+1) | F9: =IFERROR(INDEX(Events!$A:$A,MATCH(E9,Events!$G:$G,0)),"") | G9: =IF(E9="",IF(WEEKDAY($D$7,1)=MOD(startday+1,7)+1,$D$7,""),E9+1) -> 45748 | H9: W1 | I9: =IF(G9="",IF(WEEKDAY($D$7,1)=MOD(startday+2,7)+1,$D$7,""),G9+1) -> 45749 | J9: W2 | K9: =IF(I9="",IF(WEEKDAY($D$7,1)=MOD(startday+3,7)+1,$D$7,""),I9+1) -> 45750 | L9: W3 | M9: =IF(K9="",IF(WEEKDAY($D$7,1)=MOD(startday+4,7)+1,$D$7,""),K9+1) -> 45751 | N9: W4 | O9: =IF(M9="",IF(WEEKDAY($D$7,1)=MOD(startday+5,7)+1,$D$7,""),M9+1) -> 45752 | P9: W5 | R9: week 1
C10: =IFERROR(INDEX(Events!$A:$A,MATCH(C9,Events!$H:$H,0)),"") | D10: =IFERROR(INDEX(Events!#REF!,MATCH(C10,Events!A:A,0)),"") | E10: =IFERROR(INDEX(Events!$A:$A,MATCH(E9,Events!$H:$H,0)),"") | F10: =IFERROR(INDEX(Events!#REF!,MATCH(E10,Events!C:C,0)),"") | G10: WW Load Run | I10: WW courtesy run | K10: No WW Load Run | M10: No WW Load Run | O10: =IFERROR(INDEX(Events!$A:$A,MATCH(O9,Events!$H:$H,0)),"") | P10: =IFERROR(INDEX(Events!G:G,MATCH(O10,Events!K:K,0)),"")
G11: Final Load | H11: =IFERROR(INDEX(Events!#REF!,MATCH(G11,Events!E:E,0)),"") | I11: =IFERROR(INDEX(Events!$A:$A,MATCH(I8,Events!$I:$I,0)),"") | K11: =IFERROR(INDEX(Events!$A:$A,MATCH(K8,Events!$I:$I,0)),"") | M11: =IFERROR(INDEX(Events!$A:$A,MATCH(M8,Events!$I:$I,0)),"") | O11: =IFERROR(INDEX(Events!$A:$A,MATCH(O8,Events!$I:$I,0)),"")
C12: =IFERROR(INDEX(Events!$A:$A,MATCH(C9,Events!$I:$I,0)),"") | E12: =IFERROR(INDEX(Events!$A:$A,MATCH(E9,Events!$I:$I,0)),"") | I12: =IFERROR(INDEX(Events!$A:$A,MATCH(I9,Events!$I:$I,0)),"") | K12: =IFERROR(INDEX(Events!$A:$A,MATCH(K9,Events!$I:$I,0)),"") | M12: =IFERROR(INDEX(Events!$A:$A,MATCH(M9,Events!$I:$I,0)),"") | O12: =IFERROR(INDEX(Events!$A:$A,MATCH(O9,Events!$I:$I,0)),"")
C13: =IFERROR(INDEX(Events!$A:$A,MATCH(C9,Events!$J:$J,0)),"") | E13: =IFERROR(INDEX(Events!$A:$A,MATCH(E9,Events!$J:$J,0)),"") | G13: Blackout | I13: =IFERROR(INDEX(Events!$A:$A,MATCH(I9,Events!$J:$J,0)),"") | K13: =IFERROR(INDEX(Events!$A:$A,MATCH(K9,Events!$J:$J,0)),"") | M13: =IFERROR(INDEX(Events!$A:$A,MATCH(M9,Events!$J:$J,0)),"") | O13: =IFERROR(INDEX(Events!$A:$A,MATCH(O9,Events!$J:$J,0)),"")
C14: =IF(O9="","",IF(MONTH(O9+1)<>MONTH(O9),"",O9+1)) -> 45753 | D14: =IFERROR(INDEX(Events!$A:$A,MATCH(C14,Events!$G:$G,0)),"") | E14: =IF(C14="","",IF(MONTH(C14+1)<>MONTH(C14),"",C14+1)) -> 45754 | F14: W6 | G14: =IF(E14="","",IF(MONTH(E14+1)<>MONTH(E14),"",E14+1)) -> 45755 | H14: W7 | I14: =IF(G14="","",IF(MONTH(G14+1)<>MONTH(G14),"",G14+1)) -> 45756 | J14: W8 | K14: =IF(I14="","",IF(MONTH(I14+1)<>MONTH(I14),"",I14+1)) -> 45757 | L14: W9 | M14: =IF(K14="","",IF(MONTH(K14+1)<>MONTH(K14),"",K14+1)) -> 45758 | N14: W10 | O14: =IF(M14="","",IF(MONTH(M14+1)<>MONTH(M14),"",M14+1)) -> 45759 | P14: =IFERROR(INDEX(Events!$A:$A,MATCH(O14,Events!$G:$G,0)),"") | R14: week 2
C15: No WW Load Run | E15: No WW Load Run | G15: No WW Load Run | I15: GTN update | J15: =IFERROR(INDEX(Events!A:A,MATCH(I15,Events!#REF!,0)),"") | K15: =IFERROR(INDEX(Events!$A:$A,MATCH(K14,Events!$H:$H,0)),"") | L15: =IFERROR(INDEX(Events!#REF!,MATCH(K15,Events!I:I,0)),"") | M15: =IFERROR(INDEX(Events!$A:$A,MATCH(M14,Events!$H:$H,0)),"") | N15: =IFERROR(INDEX(Events!#REF!,MATCH(M15,Events!K:K,0)),"") | O15: =IFERROR(INDEX(Events!$A:$A,MATCH(O14,Events!$H:$H,0)),"") | P15: =IFERROR(INDEX(Events!#REF!,MATCH(O15,Events!M:M,0)),"")
C16: =IFERROR(INDEX(Events!$A:$A,MATCH(C14,Events!$H:$H,0)),"") | D16: =IFERROR(INDEX(Events!#REF!,MATCH(C16,Events!A:A,0)),"") | E16: =IFERROR(INDEX(Events!$A:$A,MATCH(E14,Events!$H:$H,0)),"") | F16: =IFERROR(INDEX(Events!#REF!,MATCH(E16,Events!C:C,0)),"") | G16: AUR valuation | I16: Roll to next qtr | J16: =IFERROR(INDEX(Events!#REF!,MATCH(I16,Events!G:G,0)),"") | K16: =IFERROR(INDEX(Events!$A:$A,MATCH(K14,Events!$H:$H,0)),"") | L16: =IFERROR(INDEX(Events!#REF!,MATCH(K16,Events!I:I,0)),"") | M16: =IFERROR(INDEX(Events!$A:$A,MATCH(M14,Events!$H:$H,0)),"") | N16: =IFERROR(INDEX(Events!#REF!,MATCH(M16,Events!K:K,0)),"") | O16: =IFERROR(INDEX(Events!$A:$A,MATCH(O14,Events!$H:$H,0)),"") | P16: =IFERROR(INDEX(Events!#REF!,MATCH(O16,Events!M:M,0)),"")
C17: =IFERROR(INDEX(Events!$A:$A,MATCH(C14,Events!$I:$I,0)),"") | E17: =IFERROR(INDEX(Events!$A:$A,MATCH(E14,Events!$I:$I,0)),"") | G17: =IFERROR(INDEX(Events!$A:$A,MATCH(G15,Events!$H:$H,0)),"") | H17: =IFERROR(INDEX(Events!#REF!,MATCH(G17,Events!E:E,0)),"") | I17: WW Load Run | K17: WW Load Run | M17: WW Load Run | O17: =IFERROR(INDEX(Events!$A:$A,MATCH(O14,Events!$I:$I,0)),"")
C18: =IFERROR(INDEX(Events!$A:$A,MATCH(C14,Events!$J:$J,0)),"") | E18: =IFERROR(INDEX(Events!$A:$A,MATCH(E14,Events!$J:$J,0)),"") | G18: =IFERROR(INDEX(Events!$A:$A,MATCH(G14,Events!$J:$J,0)),"") | I18: Daily Load report | K18: Daily Load report | M18: Daily Load report | O18: =IFERROR(INDEX(Events!$A:$A,MATCH(O14,Events!$J:$J,0)),"")
C19: =IF(O14="","",IF(MONTH(O14+1)<>MONTH(O14),"",O14+1)) -> 45760 | E19: =IF(C19="","",IF(MONTH(C19+1)<>MONTH(C19),"",C19+1)) -> 45761 | F19: =IFERROR(INDEX(Events!$A:$A,MATCH(E19,Events!$G:$G,0)),"") | G19: =IF(E19="","",IF(MONTH(E19+1)<>MONTH(E19),"",E19+1)) -> 45762 | I19: =IF(G19="","",IF(MONTH(G19+1)<>MONTH(G19),"",G19+1)) -> 45763 | J19: =IFERROR(INDEX(Events!$A:$A,MATCH(I19,Events!$G:$G,0)),"") | K19: =IF(I19="","",IF(MONTH(I19+1)<>MONTH(I19),"",I19+1)) -> 45764 | L19: =IFERROR(INDEX(Events!$A:$A,MATCH(K19,Events!$G:$G,0)),"") | M19: =IF(K19="","",IF(MONTH(K19+1)<>MONTH(K19),"",K19+1)) -> 45765 | N19: =IFERROR(INDEX(Events!$A:$A,MATCH(M19,Events!$G:$G,0)),"") -> Good Friday | O19: =IF(M19="","",IF(MONTH(M19+1)<>MONTH(M19),"",M19+1)) -> 45766 | P19: =IFERROR(INDEX(Events!$A:$A,MATCH(O19,Events!$G:$G,0)),"") | R19: week 3
C20: =IFERROR(INDEX(Events!$A:$A,MATCH(C19,Events!$H:$H,0)),"") | D20: =IFERROR(INDEX(Events!#REF!,MATCH(C20,Events!A:A,0)),"") | E20: =IFERROR(INDEX(Events!$A:$A,MATCH(E19,Events!$H:$H,0)),"") | F20: =IFERROR(INDEX(Events!#REF!,MATCH(E20,Events!C:C,0)),"") | G20: =IFERROR(INDEX(Events!$A:$A,MATCH(G19,Events!$H:$H,0)),"") | H20: =IFERROR(INDEX(Events!#REF!,MATCH(G20,Events!E:E,0)),"") | I20: =IFERROR(INDEX(Events!$A:$A,MATCH(I19,Events!$H:$H,0)),"") | J20: =IFERROR(INDEX(Events!#REF!,MATCH(I20,Events!G:G,0)),"") | K20: =IFERROR(INDEX(Events!$A:$A,MATCH(K19,Events!$H:$H,0)),"") | L20: =IFERROR(INDEX(Events!#REF!,MATCH(K20,Events!I:I,0)),"") | M20: =IFERROR(INDEX(Events!$A:$A,MATCH(M19,Events!$H:$H,0)),"") | N20: =IFERROR(INDEX(Events!#REF!,MATCH(M20,Events!K:K,0)),"") | O20: =IFERROR(INDEX(Events!$A:$A,MATCH(O19,Events!$H:$H,0)),"") | P20: =IFERROR(INDEX(Events!#REF!,MATCH(O20,Events!M:M,0)),"")
C21: WW Load Run | E21: WW Load Run | G21: WW Load Run | I21: WW Load Run | K21: WW Load Run | M21: WW Load Run | O21: =IFERROR(INDEX(Events!$A:$A,MATCH(O19,Events!$H:$H,0)),"") | P21: =IFERROR(INDEX(Events!#REF!,MATCH(O21,Events!M:M,0)),"")
C22: =IFERROR(INDEX(Events!$A:$A,MATCH(C19,Events!$I:$I,0)),"") | E22: EPM Dashboard | G22: =IFERROR(INDEX(Events!$A:$A,MATCH(G19,Events!$I:$I,0)),"") | I22: =IFERROR(INDEX(Events!$A:$A,MATCH(I19,Events!$I:$I,0)),"") | K22: =IFERROR(INDEX(Events!$A:$A,MATCH(K19,Events!$I:$I,0)),"") | M22: =IFERROR(INDEX(Events!$A:$A,MATCH(M19,Events!$I:$I,0)),"") | O22: =IFERROR(INDEX(Events!$A:$A,MATCH(O19,Events!$I:$I,0)),"")
C23: =IFERROR(INDEX(Events!$A:$A,MATCH(C19,Events!$J:$J,0)),"") | E23: Daily Load report | G23: Daily Load report | I23: Daily Load report | K23: Daily Load report | M23: Daily Load report | O23: =IFERROR(INDEX(Events!$A:$A,MATCH(O19,Events!$J:$J,0)),"")
C24: =IF(O19="","",IF(MONTH(O19+1)<>MONTH(O19),"",O19+1)) -> 45767 | D24: =IFERROR(INDEX(Events!$A:$A,MATCH(C24,Events!$G:$G,0)),"") -> Easter | E24: =IF(C24="","",IF(MONTH(C24+1)<>MONTH(C24),"",C24+1)) -> 45768 | F24: =IFERROR(INDEX(Events!$A:$A,MATCH(E24,Events!$G:$G,0)),"") | G24: =IF(E24="","",IF(MONTH(E24+1)<>MONTH(E24),"",E24+1)) -> 45769 | I24: =IF(G24="","",IF(MONTH(G24+1)<>MONTH(G24),"",G24+1)) -> 45770 | K24: =IF(I24="","",IF(MONTH(I24+1)<>MONTH(I24),"",I24+1)) -> 45771 | L24: =IFERROR(INDEX(Events!$A:$A,MATCH(K24,Events!$G:$G,0)),"") | M24: =IF(K24="","",IF(MONTH(K24+1)<>MONTH(K24),"",K24+1)) -> 45772 | N24: =IFERROR(INDEX(Events!$A:$A,MATCH(M24,Events!$G:$G,0)),"") | O24: =IF(M24="","",IF(MONTH(M24+1)<>MONTH(M24),"",M24+1)) -> 45773 | P24: =IFERROR(INDEX(Events!$A:$A,MATCH(O24,Events!$G:$G,0)),"") | R24: week 4
C25: =IFERROR(INDEX(Events!$A:$A,MATCH(C24,Events!$H:$H,0)),"") | D25: =IFERROR(INDEX(Events!#REF!,MATCH(C25,Events!A:A,0)),"") | E25: =IFERROR(INDEX(Events!$A:$A,MATCH(E24,Events!$H:$H,0)),"") | F25: =IFERROR(INDEX(Events!#REF!,MATCH(E25,Events!C:C,0)),"") | G25: =IFERROR(INDEX(Events!$A:$A,MATCH(G24,Events!$H:$H,0)),"") | H25: =IFERROR(INDEX(Events!#REF!,MATCH(G25,Events!E:E,0)),"") | I25: PRELIM EARNINGS | J25: =IFERROR(INDEX(Events!A:A,MATCH(I25,Events!G:G,0)),"") | K25: =IFERROR(INDEX(Events!$A:$A,MATCH(K24,Events!$H:$H,0)),"") | L25: =IFERROR(INDEX(Events!#REF!,MATCH(K25,Events!I:I,0)),"") | M25: =IFERROR(INDEX(Events!$A:$A,MATCH(M24,Events!$H:$H,0)),"") | N25: =IFERROR(INDEX(Events!#REF!,MATCH(M25,Events!K:K,0)),"") | O25: =IFERROR(INDEX(Events!$A:$A,MATCH(O24,Events!$H:$H,0)),"") | P25: =IFERROR(INDEX(Events!#REF!,MATCH(O25,Events!M:M,0)),"")
C26: WW Load Run | E26: WW Load Run | G26: WW Load Run | I26: WW Load Run | K26: WW Load Run | M26: WW Load Run | O26: =IFERROR(INDEX(Events!$A:$A,MATCH(O24,Events!$H:$H,0)),"") | P26: =IFERROR(INDEX(Events!#REF!,MATCH(O26,Events!M:M,0)),"")
C27: =IFERROR(INDEX(Events!$A:$A,MATCH(C24,Events!$I:$I,0)),"") | E27: EPM Dashboard | G27: =IFERROR(INDEX(Events!$A:$A,MATCH(G24,Events!$I:$I,0)),"") | I27: =IFERROR(INDEX(Events!$A:$A,MATCH(I24,Events!$I:$I,0)),"") | K27: =IFERROR(INDEX(Events!$A:$A,MATCH(K24,Events!$I:$I,0)),"") | M27: =IFERROR(INDEX(Events!$A:$A,MATCH(M24,Events!$I:$I,0)),"") | O27: =IFERROR(INDEX(Events!$A:$A,MATCH(O24,Events!$I:$I,0)),"")
C28: =IFERROR(INDEX(Events!$A:$A,MATCH(C24,Events!$J:$J,0)),"") | E28: Daily Load report | G28: Daily Load report | I28: Daily Load report | K28: Daily Load report | M28: Daily Load report | O28: =IFERROR(INDEX(Events!$A:$A,MATCH(O24,Events!$J:$J,0)),"")
C29: =IF(O24="","",IF(MONTH(O24+1)<>MONTH(O24),"",O24+1)) -> 45774 | D29: =IFERROR(INDEX(Events!$A:$A,MATCH(C29,Events!$G:$G,0)),"") | E29: =IF(C29="","",IF(MONTH(C29+1)<>MONTH(C29),"",C29+1)) -> 45775 | F29: =IFERROR(INDEX(Events!$A:$A,MATCH(E29,Events!$G:$G,0)),"") | G29: =IF(E29="","",IF(MONTH(E29+1)<>MONTH(E29),"",E29+1)) -> 45776 | H29: =IFERROR(INDEX(Events!$A:$A,MATCH(G29,Events!$G:$G,0)),"") | I29: =IF(G29="","",IF(MONTH(G29+1)<>MONTH(G29),"",G29+1)) -> 45777 | J29: =IFERROR(INDEX(Events!$A:$A,MATCH(I29,Events!$G:$G,0)),"") | K29: =IF(I29="","",IF(MONTH(I29+1)<>MONTH(I29),"",I29+1)) | L29: =IFERROR(INDEX(Events!$A:$A,MATCH(K29,Events!$G:$G,0)),"") | M29: =IF(K29="","",IF(MONTH(K29+1)<>MONTH(K29),"",K29+1)) | N29: =IFERROR(INDEX(Events!$A:$A,MATCH(M29,Events!$G:$G,0)),"") | O29: =IF(M29="","",IF(MONTH(M29+1)<>MONTH(M29),"",M29+1)) | P29: =IFERROR(INDEX(Events!$A:$A,MATCH(O29,Events!$G:$G,0)),"") | R29: week 5
C30: =IFERROR(INDEX(Events!$A:$A,MATCH(C29,Events!$H:$H,0)),"") | D30: =IFERROR(INDEX(Events!#REF!,MATCH(C30,Events!A:A,0)),"") | E30: =IFERROR(INDEX(Events!$A:$A,MATCH(E28,Events!$H:$H,0)),"") | F30: =IFERROR(INDEX(Events!#REF!,MATCH(E30,Events!C:C,0)),"") | G30: =IFERROR(INDEX(Events!$A:$A,MATCH(G28,Events!$H:$H,0)),"") | H30: =IFERROR(INDEX(Events!#REF!,MATCH(G30,Events!E:E,0)),"") | I30: =IFERROR(INDEX(Events!$A:$A,MATCH(I28,Events!$H:$H,0)),"") | J30: =IFERROR(INDEX(Events!A:A,MATCH(I30,Events!G:G,0)),"")
C31: WW Load Run | E31: WW Load Run | G31: WW Load Run | I31: WW Load Run | K31: =IFERROR(INDEX(Events!$A:$A,MATCH(K29,Events!$H:$H,0)),"") | L31: =IFERROR(INDEX(Events!C:C,MATCH(K31,Events!I:I,0)),"") | M31: =IFERROR(INDEX(Events!$A:$A,MATCH(M29,Events!$H:$H,0)),"") | N31: =IFERROR(INDEX(Events!E:E,MATCH(M31,Events!#REF!,0)),"") | O31: =IFERROR(INDEX(Events!$A:$A,MATCH(O29,Events!$H:$H,0)),"") | P31: =IFERROR(INDEX(Events!G:G,MATCH(O31,Events!K:K,0)),"")
C32: =IFERROR(INDEX(Events!$A:$A,MATCH(C29,Events!$I:$I,0)),"") | E32: EPM Dashboard | G32: EPM Dashboard | I32: EPM Dashboard | K32: =IFERROR(INDEX(Events!$A:$A,MATCH(K29,Events!$I:$I,0)),"") | M32: =IFERROR(INDEX(Events!$A:$A,MATCH(M29,Events!$I:$I,0)),"") | O32: =IFERROR(INDEX(Events!$A:$A,MATCH(O29,Events!$I:$I,0)),"")
C33: =IFERROR(INDEX(Events!$A:$A,MATCH(C29,Events!$J:$J,0)),"") | E33: Daily Load report | G33: Daily Load report | I33: Daily Load report | K33: =IFERROR(INDEX(Events!$A:$A,MATCH(K29,Events!$J:$J,0)),"") | M33: =IFERROR(INDEX(Events!$A:$A,MATCH(M29,Events!$J:$J,0)),"") | O33: =IFERROR(INDEX(Events!$A:$A,MATCH(O29,Events!$J:$J,0)),"")
C34: =IF(O29="","",IF(MONTH(O29+1)<>MONTH(O29),"",O29+1)) | D34: =IFERROR(INDEX(Events!$A:$A,MATCH(C34,Events!$G:$G,0)),"") | E34: =IF(C34="","",IF(MONTH(C34+1)<>MONTH(C34),"",C34+1)) | F34: =IFERROR(INDEX(Events!$A:$A,MATCH(E34,Events!$G:$G,0)),"")
C35: =IFERROR(INDEX(Events!$A:$A,MATCH(C34,Events!$H:$H,0)),"") | D35: =IFERROR(INDEX(Events!#REF!,MATCH(C35,Events!A:A,0)),"") | E35: =IFERROR(INDEX(Events!$A:$A,MATCH(E34,Events!$H:$H,0)),"") | F35: =IFERROR(INDEX(Events!#REF!,MATCH(E35,Events!C:C,0)),"")
C36: =IFERROR(INDEX(Events!$A:$A,MATCH(C34,Events!$I:$I,0)),"") | E36: =IFERROR(INDEX(Events!$A:$A,MATCH(E34,Events!$I:$I,0)),"")
C37: =IFERROR(INDEX(Events!$A:$A,MATCH(C34,Events!$J:$J,0)),"") | E37: =IFERROR(INDEX(Events!$A:$A,MATCH(E34,Events!$J:$J,0)),"")
C39: Date: | D39: =DATE(YEAR('Q1'!$D$7),MONTH('Q1'!$D$7)+4,1) -> 45778
A40: =D39 -> 45778 | C40: Sunday | E40: Monday | G40: Tuesday | I40: Wednesday | K40: Thursday | M40: Friday | O40: Saturday | R40: week
C41: =IF(WEEKDAY($D$39,1)=startday,$D$39,"") | D41: =IFERROR(INDEX(Events!$A:$A,MATCH(C41,Events!$G:$G,0)),"") | E41: =IF(C41="",IF(WEEKDAY($D$39,1)=MOD(startday,7)+1,$D$39,""),C41+1) | F41: =IFERROR(INDEX(Events!$A:$A,MATCH(E41,Events!$G:$G,0)),"") | G41: =IF(E41="",IF(WEEKDAY($D$39,1)=MOD(startday+1,7)+1,$D$39,""),E41+1) | H41: =IFERROR(INDEX(Events!$A:$A,MATCH(G41,Events!$G:$G,0)),"") | I41: =IF(G41="",IF(WEEKDAY($D$39,1)=MOD(startday+2,7)+1,$D$39,""),G41+1) | J41: =IFERROR(INDEX(Events!$A:$A,MATCH(I41,Events!$G:$G,0)),"") | K41: =IF(I41="",IF(WEEKDAY($D$39,1)=MOD(startday+3,7)+1,$D$39,""),I41+1) -> 45778 | L41: =IFERROR(INDEX(Events!$A:$A,MATCH(K41,Events!$G:$G,0)),"") | M41: =IF(K41="",IF(WEEKDAY($D$39,1)=MOD(startday+4,7)+1,$D$39,""),K41+1) -> 45779 | N41: W1 | O41: =IF(M41="",IF(WEEKDAY($D$39,1)=MOD(startday+5,7)+1,$D$39,""),M41+1) -> 45780 | P41: =IFERROR(INDEX(Events!$A:$A,MATCH(O41,Events!$G:$G,0)),"") | R41: week 5 (cont)
C42: =IFERROR(INDEX(Events!$A:$A,MATCH(C41,Events!$H:$H,0)),"") | E42: =IFERROR(INDEX(Events!$A:$A,MATCH(E41,Events!$H:$H,0)),"") | G42: =IFERROR(INDEX(Events!$A:$A,MATCH(G41,Events!$H:$H,0)),"") | I42: =IFERROR(INDEX(Events!$A:$A,MATCH(I41,Events!$H:$H,0)),"") | K42: LABOR DAY | M42: April Final | O42: =IFERROR(INDEX(Events!$A:$A,MATCH(O41,Events!$H:$H,0)),"")
C43: =IFERROR(INDEX(Events!$A:$A,MATCH(C41,Events!$I:$I,0)),"") | E43: =IFERROR(INDEX(Events!$A:$A,MATCH(E41,Events!$I:$I,0)),"") | G43: =IFERROR(INDEX(Events!$A:$A,MATCH(G41,Events!$I:$I,0)),"") | I43: =IFERROR(INDEX(Events!$A:$A,MATCH(I41,Events!$I:$I,0)),"") | K43: NON-US | M43: EPM Dashboard | O43: =IFERROR(INDEX(Events!$A:$A,MATCH(O41,Events!$I:$I,0)),"")
O44: =IFERROR(INDEX(Events!$A:$A,MATCH(O43,Events!$H:$H,0)),"")
C45: =IFERROR(INDEX(Events!$A:$A,MATCH(C41,Events!$J:$J,0)),"") | E45: =IFERROR(INDEX(Events!$A:$A,MATCH(E41,Events!$J:$J,0)),"") | G45: =IFERROR(INDEX(Events!$A:$A,MATCH(G41,Events!$J:$J,0)),"") | I45: =IFERROR(INDEX(Events!$A:$A,MATCH(I41,Events!$J:$J,0)),"") | K45: =IFERROR(INDEX(Events!$A:$A,MATCH(K41,Events!$J:$J,0)),"") | M45: Daily Load report | O45: =IFERROR(INDEX(Events!$A:$A,MATCH(O41,Events!$J:$J,0)),"")
C46: =IF(O41="","",IF(MONTH(O41+1)<>MONTH(O41),"",O41+1)) -> 45781 | D46: =IFERROR(INDEX(Events!$A:$A,MATCH(C46,Events!$G:$G,0)),"") | E46: =IF(C46="","",IF(MONTH(C46+1)<>MONTH(C46),"",C46+1)) -> 45782 | F46: W2 | G46: =IF(E46="","",IF(MONTH(E46+1)<>MONTH(E46),"",E46+1)) -> 45783 | H46: W3 | I46: =IF(G46="","",IF(MONTH(G46+1)<>MONTH(G46),"",G46+1)) -> 45784 | J46: W4 | K46: =IF(I46="","",IF(MONTH(I46+1)<>MONTH(I46),"",I46+1)) -> 45785 | L46: W5 | M46: =IF(K46="","",IF(MONTH(K46+1)<>MONTH(K46),"",K46+1)) -> 45786 | N46: W6 | O46: =IF(M46="","",IF(MONTH(M46+1)<>MONTH(M46),"",M46+1)) -> 45787 | P46: =IFERROR(INDEX(Events!$A:$A,MATCH(O46,Events!$G:$G,0)),"") | R46: week 6
...

Sheet Q4
C5: Load Calendar
C7: Date: | D7: =DATE(YEAR('Q1'!$D$7),MONTH('Q1'!$D$7)+9,1) -> 45931
A8: =D7 -> 45931 | C8: Sunday | E8: Monday | G8: Tuesday | I8: Wednesday | K8: Thursday | M8: Friday | O8: Saturday | R8: week
C9: =IF(WEEKDAY($D$7,1)=startday,$D$7,"") | D9: =IFERROR(INDEX(Events!$A:$A,MATCH(C9,Events!$G:$G,0)),"") | E9: =IF(C9="",IF(WEEKDAY($D$7,1)=MOD(startday,7)+1,$D$7,""),C9+1) | F9: =IFERROR(INDEX(Events!$A:$A,MATCH(E9,Events!$G:$G,0)),"") | G9: =IF(E9="",IF(WEEKDAY($D$7,1)=MOD(startday+1,7)+1,$D$7,""),E9+1) | H9: =IFERROR(INDEX(Events!$A:$A,MATCH(G9,Events!$G:$G,0)),"") | I9: =IF(G9="",IF(WEEKDAY($D$7,1)=MOD(startday+2,7)+1,$D$7,""),G9+1) -> 45931 | J9: W1 | K9: =IF(I9="",IF(WEEKDAY($D$7,1)=MOD(startday+2,7)+1,$D$7,""),I9+1) -> 45932 | L9: W2 | M9: =IF(K9="",IF(WEEKDAY($D$7,1)=MOD(startday+3,7)+1,$D$7,""),K9+1) -> 45933 | N9: W3 | O9: =IF(M9="",IF(WEEKDAY($D$7,1)=MOD(startday+4,7)+1,$D$7,""),M9+1) -> 45934 | R9: week 1
I10: Final Load | J10: =IFERROR(INDEX(Events!#REF!,MATCH(I10,Events!G:G,0)),"") | K10: WW courtesy run | M10: No WW Load Run | O10: =IFERROR(INDEX(Events!$A:$A,MATCH(O8,Events!$H:$H,0)),"") | P10: =IFERROR(INDEX(Events!G:G,MATCH(O10,Events!K:K,0)),"")
C11: =IFERROR(INDEX(Events!$A:$A,MATCH(C9,Events!$H:$H,0)),"") | D11: =IFERROR(INDEX(Events!#REF!,MATCH(C11,Events!A:A,0)),"") | E11: =IFERROR(INDEX(Events!$A:$A,MATCH(E9,Events!$H:$H,0)),"") | F11: =IFERROR(INDEX(Events!#REF!,MATCH(E11,Events!C:C,0)),"") | G11: =IFERROR(INDEX(Events!$A:$A,MATCH(G9,Events!$H:$H,0)),"") | H11: =IFERROR(INDEX(Events!#REF!,MATCH(G11,Events!E:E,0)),"") | I11: WW Load Run | K11: =IFERROR(INDEX(Events!$A:$A,MATCH(K10,Events!$H:$H,0)),"") | M11: =IFERROR(INDEX(Events!$A:$A,MATCH(M10,Events!$H:$H,0)),"") | O11: =IFERROR(INDEX(Events!$A:$A,MATCH(O9,Events!$H:$H,0)),"") | P11: =IFERROR(INDEX(Events!G:G,MATCH(O11,Events!K:K,0)),"")
C12: =IFERROR(INDEX(Events!$A:$A,MATCH(C9,Events!$I:$I,0)),"") | E12: =IFERROR(INDEX(Events!$A:$A,MATCH(E9,Events!$I:$I,0)),"") | G12: =IFERROR(INDEX(Events!$A:$A,MATCH(G9,Events!$I:$I,0)),"") | K12: =IFERROR(INDEX(Events!$A:$A,MATCH(K9,Events!$I:$I,0)),"") | M12: =IFERROR(INDEX(Events!$A:$A,MATCH(M9,Events!$I:$I,0)),"") | O12: =IFERROR(INDEX(Events!$A:$A,MATCH(O9,Events!$I:$I,0)),"")
C13: =IFERROR(INDEX(Events!$A:$A,MATCH(C9,Events!$J:$J,0)),"") | E13: =IFERROR(INDEX(Events!$A:$A,MATCH(E9,Events!$J:$J,0)),"") | G13: =IFERROR(INDEX(Events!$A:$A,MATCH(G9,Events!$J:$J,0)),"") | I13: Blackout | K13: =IFERROR(INDEX(Events!$A:$A,MATCH(K9,Events!$J:$J,0)),"") | M13: =IFERROR(INDEX(Events!$A:$A,MATCH(M9,Events!$J:$J,0)),"") | O13: =IFERROR(INDEX(Events!$A:$A,MATCH(O9,Events!$J:$J,0)),"")
C14: =IF(O9="","",IF(MONTH(O9+1)<>MONTH(O9),"",O9+1)) -> 45935 | D14: =IFERROR(INDEX(Events!$A:$A,MATCH(C14,Events!$G:$G,0)),"") | E14: =IF(C14="","",IF(MONTH(C14+1)<>MONTH(C14),"",C14+1)) -> 45936 | F14: W4 | G14: =IF(E14="","",IF(MONTH(E14+1)<>MONTH(E14),"",E14+1)) -> 45937 | H14: W5 | I14: =IF(G14="","",IF(MONTH(G14+1)<>MONTH(G14),"",G14+1)) -> 45938 | J14: W6 | K14: =IF(I14="","",IF(MONTH(I14+1)<>MONTH(I14),"",I14+1)) -> 45939 | L14: W7 | M14: =IF(K14="","",IF(MONTH(K14+1)<>MONTH(K14),"",K14+1)) -> 45940 | N14: W8 | O14: =IF(M14="","",IF(MONTH(M14+1)<>MONTH(M14),"",M14+1)) -> 45941 | P14: =IFERROR(INDEX(Events!$A:$A,MATCH(O14,Events!$G:$G,0)),"") | R14: week 2
C15: No WW Load Run | E15: No WW Load Run | G15: No WW Load Run | I15: No WW Load Run | K15: WW Load Run | M15: WW Load Run | O15: =IFERROR(INDEX(Events!$A:$A,MATCH(O14,Events!$H:$H,0)),"")
C16: =IFERROR(INDEX(Events!$A:$A,MATCH(C14,Events!$H:$H,0)),"") | D16: =IFERROR(INDEX(Events!#REF!,MATCH(C16,Events!A:A,0)),"") | E16: =IFERROR(INDEX(Events!$A:$A,MATCH(E14,Events!$H:$H,0)),"") | F16: =IFERROR(INDEX(Events!#REF!,MATCH(E16,Events!C:C,0)),"") | G16: =IFERROR(INDEX(Events!$A:$A,MATCH(G14,Events!$H:$H,0)),"") | H16: =IFERROR(INDEX(Events!#REF!,MATCH(G16,Events!E:E,0)),"") | I16: Roll to next qtr | J16: =IFERROR(INDEX(Events!#REF!,MATCH(I16,Events!G:G,0)),"") | K16: EPM Dashboard | M16: EPM Dashboard | O16: =IFERROR(INDEX(Events!$A:$A,MATCH(O14,Events!$H:$H,0)),"") | P16: =IFERROR(INDEX(Events!G:G,MATCH(O16,Events!K:K,0)),"")
C17: =IFERROR(INDEX(Events!$A:$A,MATCH(C14,Events!$I:$I,0)),"") | E17: =IFERROR(INDEX(Events!$A:$A,MATCH(E14,Events!$I:$I,0)),"") | G17: =IFERROR(INDEX(Events!$A:$A,MATCH(G14,Events!$I:$I,0)),"") | I17: AUR valuation | K17: Daily Load report | M17: Daily Load report | O17: =IFERROR(INDEX(Events!$A:$A,MATCH(O14,Events!$I:$I,0)),"")
C18: =IFERROR(INDEX(Events!$A:$A,MATCH(C14,Events!$J:$J,0)),"") | E18: =IFERROR(INDEX(Events!$A:$A,MATCH(E14,Events!$J:$J,0)),"") | G18: =IFERROR(INDEX(Events!$A:$A,MATCH(G14,Events!$J:$J,0)),"") | I18: =IFERROR(INDEX(Events!$A:$A,MATCH(I14,Events!$J:$J,0)),"") | K18: GTN update | L18: =IFERROR(INDEX([1]Events!C:C,MATCH(K18,[1]Events!#REF!,0)),"") | M18: =IFERROR(INDEX(Events!$A:$A,MATCH(M14,Events!$J:$J,0)),"") | O18: =IFERROR(INDEX(Events!$A:$A,MATCH(O14,Events!$J:$J,0)),"")
C19: =IF(O14="","",IF(MONTH(O14+1)<>MONTH(O14),"",O14+1)) -> 45942 | D19: =IFERROR(INDEX(Events!$A:$A,MATCH(C19,Events!$G:$G,0)),"") | E19: =IF(C19="","",IF(MONTH(C19+1)<>MONTH(C19),"",C19+1)) -> 45943 | F19: =IFERROR(INDEX(Events!$A:$A,MATCH(E19,Events!$G:$G,0)),"") -> Columbus Day | G19: =IF(E19="","",IF(MONTH(E19+1)<>MONTH(E19),"",E19+1)) -> 45944 | H19: =IFERROR(INDEX(Events!$A:$A,MATCH(G19,Events!$G:$G,0)),"") | I19: =IF(G19="","",IF(MONTH(G19+1)<>MONTH(G19),"",G19+1)) -> 45945 | J19: =IFERROR(INDEX(Events!$A:$A,MATCH(I19,Events!$G:$G,0)),"") | K19: =IF(I19="","",IF(MONTH(I19+1)<>MONTH(I19),"",I19+1)) -> 45946 | L19: =IFERROR(INDEX(Events!$A:$A,MATCH(K19,Events!$G:$G,0)),"") -> Boss's Day | M19: =IF(K19="","",IF(MONTH(K19+1)<>MONTH(K19),"",K19+1)) -> 45947 | N19: =IFERROR(INDEX(Events!$A:$A,MATCH(M19,Events!$G:$G,0)),"") | O19: =IF(M19="","",IF(MONTH(M19+1)<>MONTH(M19),"",M19+1)) -> 45948 | P19: =IFERROR(INDEX(Events!$A:$A,MATCH(O19,Events!$G:$G,0)),"") | R19: week 3
E20: WW Load Run | G20: WW Load Run | I20: WW Load Run | K20: WW Load Run | M20: WW Load Run | O20: =IFERROR(INDEX(Events!$A:$A,MATCH(O19,Events!$H:$H,0)),"")
E21: EPM Dashboard | G21: EPM Dashboard | I21: EPM Dashboard | K21: EPM Dashboard | M21: EPM Dashboard | O21: =IFERROR(INDEX(Events!$A:$A,MATCH(O19,Events!$H:$H,0)),"") | P21: =IFERROR(INDEX(Events!G:G,MATCH(O21,Events!K:K,0)),"")
E22: Daily Load report | G22: Daily Load report | I22: Daily Load report | K22: Daily Load report | M22: Daily Load report | O22: =IFERROR(INDEX(Events!$A:$A,MATCH(O19,Events!$I:$I,0)),"")
C23: =IFERROR(INDEX(Events!$A:$A,MATCH(C19,Events!$J:$J,0)),"") | E23: =IFERROR(INDEX(Events!$A:$A,MATCH(E19,Events!$J:$J,0)),"") | G23: =IFERROR(INDEX(Events!$A:$A,MATCH(G19,Events!$J:$J,0)),"") | I23: =IFERROR(INDEX(Events!$A:$A,MATCH(I19,Events!$J:$J,0)),"") | K23: =IFERROR(INDEX(Events!$A:$A,MATCH(K19,Events!$J:$J,0)),"") | M23: =IFERROR(INDEX(Events!$A:$A,MATCH(M19,Events!$J:$J,0)),"") | O23: =IFERROR(INDEX(Events!$A:$A,MATCH(O19,Events!$J:$J,0)),"")
C24: =IF(O19="","",IF(MONTH(O19+1)<>MONTH(O19),"",O19+1)) -> 45949 | D24: =IFERROR(INDEX(Events!$A:$A,MATCH(C24,Events!$G:$G,0)),"") | E24: =IF(C24="","",IF(MONTH(C24+1)<>MONTH(C24),"",C24+1)) -> 45950 | F24: =IFERROR(INDEX(Events!$A:$A,MATCH(E24,Events!$G:$G,0)),"") | G24: =IF(E24="","",IF(MONTH(E24+1)<>MONTH(E24),"",E24+1)) -> 45951 | H24: =IFERROR(INDEX(Events!$A:$A,MATCH(G24,Events!$G:$G,0)),"") | I24: =IF(G24="","",IF(MONTH(G24+1)<>MONTH(G24),"",G24+1)) -> 45952 | J24: EARNING RELEASE | K24: =IF(I24="","",IF(MONTH(I24+1)<>MONTH(I24),"",I24+1)) -> 45953 | L24: =IFERROR(INDEX(Events!$A:$A,MATCH(K24,Events!$G:$G,0)),"") | M24: =IF(K24="","",IF(MONTH(K24+1)<>MONTH(K24),"",K24+1)) -> 45954 | N24: =IFERROR(INDEX(Events!$A:$A,MATCH(M24,Events!$G:$G,0)),"") -> United Nations Day | O24: =IF(M24="","",IF(MONTH(M24+1)<>MONTH(M24),"",M24+1)) -> 45955 | P24: =IFERROR(INDEX(Events!$A:$A,MATCH(O24,Events!$G:$G,0)),"") | R24: week 4
E25: WW Load Run | G25: WW Load Run | I25: WW Load Run | K25: WW Load Run | M25: WW Load Run | O25: =IFERROR(INDEX(Events!$A:$A,MATCH(O24,Events!$H:$H,0)),"")
E26: EPM Dashboard | G26: EPM Dashboard | I26: EPM Dashboard | K26: EPM Dashboard | M26: EPM Dashboard | O26: =IFERROR(INDEX(Events!$A:$A,MATCH(O24,Events!$H:$H,0)),"") | P26: =IFERROR(INDEX(Events!G:G,MATCH(O26,Events!K:K,0)),"")
E27: Daily Load report | G27: Daily Load report | I27: Daily Load report | K27: Daily Load report | M27: Daily Load report | O27: =IFERROR(INDEX(Events!$A:$A,MATCH(O24,Events!$I:$I,0)),"")
C28: =IFERROR(INDEX(Events!$A:$A,MATCH(C24,Events!$J:$J,0)),"") | E28: =IFERROR(INDEX(Events!$A:$A,MATCH(E24,Events!$J:$J,0)),"") | G28: =IFERROR(INDEX(Events!$A:$A,MATCH(G24,Events!$J:$J,0)),"") | I28: CUT-OFF CEPH, Clever, Defend | J28: =IFERROR(INDEX(Events!A:A,MATCH(I28,Events!G:G,0)),"") | K28: =IFERROR(INDEX(Events!$A:$A,MATCH(K24,Events!$J:$J,0)),"") | M28: =IFERROR(INDEX(Events!$A:$A,MATCH(M24,Events!$J:$J,0)),"") | O28: =IFERROR(INDEX(Events!$A:$A,MATCH(O24,Events!$J:$J,0)),"")
C29: =IF(O24="","",IF(MONTH(O24+1)<>MONTH(O24),"",O24+1)) -> 45956 | D29: =IFERROR(INDEX(Events!$A:$A,MATCH(C29,Events!$G:$G,0)),"") | E29: =IF(C29="","",IF(MONTH(C29+1)<>MONTH(C29),"",C29+1)) -> 45957 | F29: =IFERROR(INDEX(Events!$A:$A,MATCH(E29,Events!$G:$G,0)),"") | G29: =IF(E29="","",IF(MONTH(E29+1)<>MONTH(E29),"",E29+1)) -> 45958 | H29: =IFERROR(INDEX(Events!$A:$A,MATCH(G29,Events!$G:$G,0)),"") | I29: =IF(G29="","",IF(MONTH(G29+1)<>MONTH(G29),"",G29+1)) -> 45959 | J29: =IFERROR(INDEX(Events!$A:$A,MATCH(I29,Events!$G:$G,0)),"") | K29: =IF(I29="","",IF(MONTH(I29+1)<>MONTH(I29),"",I29+1)) -> 45960 | L29: =IFERROR(INDEX(Events!$A:$A,MATCH(K29,Events!$G:$G,0)),"") | M29: =IF(K29="","",IF(MONTH(K29+1)<>MONTH(K29),"",K29+1)) -> 45961 | N29: =IFERROR(INDEX(Events!$A:$A,MATCH(M29,Events!$G:$G,0)),"") -> Halloween | O29: =IF(M29="","",IF(MONTH(M29+1)<>MONTH(M29),"",M29+1)) | P29: =IFERROR(INDEX(Events!$A:$A,MATCH(O29,Events!$G:$G,0)),"") | R29: week 5
E30: WW Load Run | G30: WW Load Run | I30: WW Load Run | K30: WW Load Run | M30: WW Load Run | O30: =IFERROR(INDEX(Events!$A:$A,MATCH(O29,Events!$H:$H,0)),"")
E31: EPM Dashboard | G31: EPM Dashboard | I31: EPM Dashboard | K31: EPM Dashboard | M31: EPM Dashboard | O31: =IFERROR(INDEX(Events!$A:$A,MATCH(O29,Events!$H:$H,0)),"") | P31: =IFERROR(INDEX(Events!G:G,MATCH(O31,Events!K:K,0)),"")
E32: Daily Load report | G32: Daily Load report | I32: Daily Load report | K32: Daily Load report | M32: Daily Load report | O32: =IFERROR(INDEX(Events!$A:$A,MATCH(O29,Events!$I:$I,0)),"")
C33: =IFERROR(INDEX(Events!$A:$A,MATCH(C29,Events!$J:$J,0)),"") | E33: =IFERROR(INDEX(Events!$A:$A,MATCH(E29,Events!$J:$J,0)),"") | G33: =IFERROR(INDEX(Events!$A:$A,MATCH(G29,Events!$J:$J,0)),"") | I33: =IFERROR(INDEX(Events!$A:$A,MATCH(I29,Events!$J:$J,0)),"") | K33: =IFERROR(INDEX(Events!$A:$A,MATCH(K29,Events!$J:$J,0)),"") | M33: =IFERROR(INDEX(Events!$A:$A,MATCH(M29,Events!$J:$J,0)),"") | O33: =IFERROR(INDEX(Events!$A:$A,MATCH(O29,Events!$J:$J,0)),"")
